Workbook

Sheet Model
A1: بيانات المادة / Item | D1: M01 - كانون الثاني Jan 2026 | P1: M02 - شباط Feb 2026 | AB1: M03 - آذار Mar 2026 | AN1: M04 - نيسان Apr 2026 | AZ1: M05 - أيار May 2026 | BL1: M06 - حزيران Jun 2026 | BX1: M07 - تموز Jul 2026 | CJ1: M08 - آب Aug 2026 | CV1: M09 - أيلول Sep 2026 | DH1: الملخص 9 أشهر (كانون الثاني - أيلول 2026) / 9-Month Summary
A2: رقم المادة ItemNo | B2: وصف المادة ItemDesc | C2: الفئة الفرعية SubCateg | D2: رصيد بداية المدة كمية OpenQty | E2: كلفة بداية المدة OpenCost | F2: كلفة الوحدة بداية Open Unit Cost | G2: مجموع الإدخال كمية TotalInQty | H2: كلفة الإدخال InCost | I2: كلفة وحدة الإدخال In Unit Cost | J2: مجموع الإخراج كمية OutQty (+) | K2: كلفة الإخراج OutCost | L2: كلفة وحدة الإخراج Out Unit Cost | M2: رصيد نهاية المدة كمية EndQty | N2: كلفة نهاية المدة EndCost | O2: كلفة الوحدة نهاية End Unit Cost | P2: رصيد بداية المدة كمية OpenQty | Q2: كلفة بداية المدة OpenCost | R2: كلفة الوحدة بداية Open Unit Cost | S2: مجموع الإدخال كمية TotalInQty | T2: كلفة الإدخال InCost | U2: كلفة وحدة الإدخال In Unit Cost | V2: مجموع الإخراج كمية OutQty (+) | W2: كلفة الإخراج OutCost | X2: كلفة وحدة الإخراج Out Unit Cost | Y2: رصيد نهاية المدة كمية EndQty | Z2: كلفة نهاية المدة EndCost | AA2: كلفة الوحدة نهاية End Unit Cost | AB2: رصيد بداية المدة كمية OpenQty | AC2: كلفة بداية المدة OpenCost | AD2: كلفة الوحدة بداية Open Unit Cost | AE2: مجموع الإدخال كمية TotalInQty | AF2: كلفة الإدخال InCost | AG2: كلفة وحدة الإدخال In Unit Cost | AH2: مجموع الإخراج كمية OutQty (+) | AI2: كلفة الإخراج OutCost | AJ2: كلفة وحدة الإخراج Out Unit Cost | AK2: رصيد نهاية المدة كمية EndQty | AL2: كلفة نهاية المدة EndCost | AM2: كلفة الوحدة نهاية End Unit Cost | AN2: رصيد بداية المدة كمية OpenQty | AO2: كلفة بداية المدة OpenCost | AP2: كلفة الوحدة بداية Open Unit Cost | AQ2: مجموع الإدخال كمية TotalInQty | AR2: كلفة الإدخال InCost | AS2: كلفة وحدة الإدخال In Unit Cost | AT2: مجموع الإخراج كمية OutQty (+) | AU2: كلفة الإخراج OutCost | AV2: كلفة وحدة الإخراج Out Unit Cost | AW2: رصيد نهاية المدة كمية EndQty | AX2: كلفة نهاية المدة EndCost | AY2: كلفة الوحدة نهاية End Unit Cost | AZ2: رصيد بداية المدة كمية OpenQty | BA2: كلفة بداية المدة OpenCost | BB2: كلفة الوحدة بداية Open Unit Cost | BC2: مجموع الإدخال كمية TotalInQty | BD2: كلفة الإدخال InCost | BE2: كلفة وحدة الإدخال In Unit Cost | BF2: مجموع الإخراج كمية OutQty (+) | BG2: كلفة الإخراج OutCost | BH2: كلفة وحدة الإخراج Out Unit Cost | BI2: رصيد نهاية المدة كمية EndQty | BJ2: كلفة نهاية المدة EndCost | BK2: كلفة الوحدة نهاية End Unit Cost | BL2: رصيد بداية المدة كمية OpenQty | BM2: كلفة بداية المدة OpenCost | BN2: كلفة الوحدة بداية Open Unit Cost | BO2: مجموع الإدخال كمية TotalInQty | BP2: كلفة الإدخال InCost | BQ2: كلفة وحدة الإدخال In Unit Cost | BR2: مجموع الإخراج كمية OutQty (+) | BS2: كلفة الإخراج OutCost | BT2: كلفة وحدة الإخراج Out Unit Cost | BU2: رصيد نهاية المدة كمية EndQty | BV2: كلفة نهاية المدة EndCost | BW2: كلفة الوحدة نهاية End Unit Cost | BX2: رصيد بداية المدة كمية OpenQty | BY2: كلفة بداية المدة OpenCost | BZ2: كلفة الوحدة بداية Open Unit Cost | CA2: مجموع الإدخال كمية TotalInQty | CB2: كلفة الإدخال InCost | CC2: كلفة وحدة الإدخال In Unit Cost | CD2: مجموع الإخراج كمية OutQty (+) | CE2: كلفة الإخراج OutCost | CF2: كلفة وحدة الإخراج Out Unit Cost | CG2: رصيد نهاية المدة كمية EndQty | CH2: كلفة نهاية المدة EndCost | CI2: كلفة الوحدة نهاية End Unit Cost | CJ2: رصيد بداية المدة كمية OpenQty | CK2: كلفة بداية المدة OpenCost | CL2: كلفة الوحدة بداية Open Unit Cost | CM2: مجموع الإدخال كمية TotalInQty | CN2: كلفة الإدخال InCost | CO2: كلفة وحدة الإدخال In Unit Cost | CP2: مجموع الإخراج كمية OutQty (+) | CQ2: كلفة الإخراج OutCost | CR2: كلفة وحدة الإخراج Out Unit Cost | CS2: رصيد نهاية المدة كمية EndQty | CT2: كلفة نهاية المدة EndCost | CU2: كلفة الوحدة نهاية End Unit Cost | CV2: رصيد بداية المدة كمية OpenQty | CW2: كلفة بداية المدة OpenCost | CX2: كلفة الوحدة بداية Open Unit Cost | CY2: مجموع الإدخال كمية TotalInQty | CZ2: كلفة الإدخال InCost | DA2: كلفة وحدة الإدخال In Unit Cost | DB2: مجموع الإخراج كمية OutQty (+) | DC2: كلفة الإخراج OutCost | DD2: كلفة وحدة الإخراج Out Unit Cost | DE2: رصيد نهاية المدة كمية EndQty | DF2: كلفة نهاية المدة EndCost | DG2: كلفة الوحدة نهاية End Unit Cost | DH2: إجمالي الإخراج 9 أشهر كمية Total Out Qty 9M | DI2: إجمالي كلفة الإخراج 9 أشهر Total Out Cost 9M | DJ2: متوسط الاستهلاك الشهري الفعلي كمية Avg Monthly Out Qty | DK2: متوسط كلفة الاستهلاك الشهري Avg Monthly Out Cost | DL2: متوسط كلفة الوحدة الفعلية 9 أشهر Actual Avg Unit Cost 9M | DM2: كلفة الوحدة المعيارية في النظام Std Unit Cost (ItemUnitCost M09) | DN2: الفرق % بين الفعلية والمعيارية Actual vs Std % | DO2: معدل الاستهلاك الشهري في النظام System ConsMonRate9 (M09) | DP2: الفرق بين معدلنا ومعدل النظام Our Rate - System Rate | DQ2: عدد الأشهر التي فيها حركة إخراج Months with Out Movement | DR2: رصيد نهاية أيلول كمية EndQty Sep | DS2: شهور التغطية Coverage Months | DT2: تدقيق (يجب أن يكون 0) Check (=0)
A3: ='M01'!C2 | B3: ='M01'!D2 | C3: ='M01'!A2 | D3: ='M01'!E2 | E3: ='M01'!F2 | F3: =IFERROR(E3/D3,0) | G3: ='M01'!M2 | H3: =IF('M01'!AG2>0,'M01'!AG2+MAX(0,G3-'M01'!H2)*IF(AND(D3<>0,E3<>0),E3/D3,'M01'!V2),G3*IF(AND(D3<>0,E3<>0),E3/D3,'M01'!V2)) | I3: =IFERROR(H3/G3,0) | J3: =-'M01'!S2 | K3: =E3+H3-N3 | L3: =IFERROR(K3/J3,0) | M3: ='M01'!T2 | N3: ='M01'!U2 | O3: =IFERROR(N3/M3,0) | P3: ='M02'!E2 | Q3: ='M02'!F2 | R3: =IFERROR(Q3/P3,0) | S3: ='M02'!M2 | T3: =IF('M02'!AG2>0,'M02'!AG2+MAX(0,S3-'M02'!H2)*IF(AND(P3<>0,Q3<>0),Q3/P3,'M02'!V2),S3*IF(AND(P3<>0,Q3<>0),Q3/P3,'M02'!V2)) | U3: =IFERROR(T3/S3,0) | V3: =-'M02'!S2 | W3: =Q3+T3-Z3 | X3: =IFERROR(W3/V3,0) | Y3: ='M02'!T2 | Z3: ='M02'!U2 | AA3: =IFERROR(Z3/Y3,0) | AB3: ='M03'!E2 | AC3: ='M03'!F2 | AD3: =IFERROR(AC3/AB3,0) | AE3: ='M03'!M2 | AF3: =IF('M03'!AG2>0,'M03'!AG2+MAX(0,AE3-'M03'!H2)*IF(AND(AB3<>0,AC3<>0),AC3/AB3,'M03'!V2),AE3*IF(AND(AB3<>0,AC3<>0),AC3/AB3,'M03'!V2)) | AG3: =IFERROR(AF3/AE3,0) | AH3: =-'M03'!S2 | AI3: =AC3+AF3-AL3 | AJ3: =IFERROR(AI3/AH3,0) | AK3: ='M03'!T2 | AL3: ='M03'!U2 | AM3: =IFERROR(AL3/AK3,0) | AN3: ='M04'!E2 | AO3: ='M04'!F2 | AP3: =IFERROR(AO3/AN3,0) | AQ3: ='M04'!M2 | AR3: =IF('M04'!AG2>0,'M04'!AG2+MAX(0,AQ3-'M04'!H2)*IF(AND(AN3<>0,AO3<>0),AO3/AN3,'M04'!V2),AQ3*IF(AND(AN3<>0,AO3<>0),AO3/AN3,'M04'!V2)) | AS3: =IFERROR(AR3/AQ3,0) | AT3: =-'M04'!S2 | AU3: =AO3+AR3-AX3 | AV3: =IFERROR(AU3/AT3,0) | AW3: ='M04'!T2 | AX3: ='M04'!U2 | AY3: =IFERROR(AX3/AW3,0) | AZ3: ='M05'!E2 | BA3: ='M05'!F2 | BB3: =IFERROR(BA3/AZ3,0) | BC3: ='M05'!M2 | BD3: =IF('M05'!AG2>0,'M05'!AG2+MAX(0,BC3-'M05'!H2)*IF(AND(AZ3<>0,BA3<>0),BA3/AZ3,'M05'!V2),BC3*IF(AND(AZ3<>0,BA3<>0),BA3/AZ3,'M05'!V2)) | BE3: =IFERROR(BD3/BC3,0) | BF3: =-'M05'!S2 | BG3: =BA3+BD3-BJ3 | BH3: =IFERROR(BG3/BF3,0) | BI3: ='M05'!T2 | BJ3: ='M05'!U2 | BK3: =IFERROR(BJ3/BI3,0) | BL3: ='M06'!E2 | BM3: ='M06'!F2 | BN3: =IFERROR(BM3/BL3,0) | BO3: ='M06'!M2 | BP3: =IF('M06'!AG2>0,'M06'!AG2+MAX(0,BO3-'M06'!H2)*IF(AND(BL3<>0,BM3<>0),BM3/BL3,'M06'!V2),BO3*IF(AND(BL3<>0,BM3<>0),BM3/BL3,'M06'!V2)) | BQ3: =IFERROR(BP3/BO3,0) | BR3: =-'M06'!S2 | BS3: =BM3+BP3-BV3 | BT3: =IFERROR(BS3/BR3,0) | BU3: ='M06'!T2 | BV3: ='M06'!U2 | BW3: =IFERROR(BV3/BU3,0) | BX3: ='M07'!E2 | BY3: ='M07'!F2 | BZ3: =IFERROR(BY3/BX3,0) | CA3: ='M07'!M2 | CB3: =IF('M07'!AG2>0,'M07'!AG2+MAX(0,CA3-'M07'!H2)*IF(AND(BX3<>0,BY3<>0),BY3/BX3,'M07'!V2),CA3*IF(AND(BX3<>0,BY3<>0),BY3/BX3,'M07'!V2)) | CC3: =IFERROR(CB3/CA3,0) | CD3: =-'M07'!S2 | CE3: =BY3+CB3-CH3 | CF3: =IFERROR(CE3/CD3,0) | CG3: ='M07'!T2 | CH3: ='M07'!U2 | CI3: =IFERROR(CH3/CG3,0) | CJ3: ='M08'!E2 | CK3: ='M08'!F2 | CL3: =IFERROR(CK3/CJ3,0) | CM3: ='M08'!M2 | CN3: =IF('M08'!AG2>0,'M08'!AG2+MAX(0,CM3-'M08'!H2)*IF(AND(CJ3<>0,CK3<>0),CK3/CJ3,'M08'!V2),CM3*IF(AND(CJ3<>0,CK3<>0),CK3/CJ3,'M08'!V2)) | CO3: =IFERROR(CN3/CM3,0) | CP3: =-'M08'!S2 | CQ3: =CK3+CN3-CT3 | CR3: =IFERROR(CQ3/CP3,0) | CS3: ='M08'!T2 | CT3: ='M08'!U2 | CU3: =IFERROR(CT3/CS3,0) | CV3: ='M09'!E2 | CW3: ='M09'!F2 | CX3: =IFERROR(CW3/CV3,0) | CY3: ='M09'!M2 | CZ3: =IF('M09'!AG2>0,'M09'!AG2+MAX(0,CY3-'M09'!H2)*IF(AND(CV3<>0,CW3<>0),CW3/CV3,'M09'!V2),CY3*IF(AND(CV3<>0,CW3<>0),CW3/CV3,'M09'!V2)) | DA3: =IFERROR(CZ3/CY3,0) | DB3: =-'M09'!S2 | DC3: =CW3+CZ3-DF3 | DD3: =IFERROR(DC3/DB3,0) | DE3: ='M09'!T2 | DF3: ='M09'!U2 | DG3: =IFERROR(DF3/DE3,0) | DH3: =SUM(J3,V3,AH3,AT3,BF3,BR3,CD3,CP3,DB3) | DI3: =SUM(K3,W3,AI3,AU3,BG3,BS3,CE3,CQ3,DC3) | DJ3: =DH3/9 | DK3: =DI3/9 | DL3: =IFERROR(DI3/DH3,0) | DM3: ='M09'!V2 | DN3: =IFERROR(DL3/DM3-1,0) | DO3: ='M09'!AD2 | DP3: =DJ3-DO3 | DQ3: =COUNTIF(J3,">0")+COUNTIF(V3,">0")+COUNTIF(AH3,">0")+COUNTIF(AT3,">0")+COUNTIF(BF3,">0")+COUNTIF(BR3,">0")+COUNTIF(CD3,">0")+COUNTIF(CP3,">0")+COUNTIF(DB3,">0") | DR3: =DE3 | DS3: =IFERROR(DR3/DJ3,0) | DT3: =D3+SUM(G3,S3,AE3,AQ3,BC3,BO3,CA3,CM3,CY3)-SUM(J3,V3,AH3,AT3,BF3,BR3,CD3,CP3,DB3)-DE3
A4: ='M01'!C3 | B4: ='M01'!D3 | C4: ='M01'!A3 | D4: ='M01'!E3 | E4: ='M01'!F3 | F4: =IFERROR(E4/D4,0) | G4: ='M01'!M3 | H4: =IF('M01'!AG3>0,'M01'!AG3+MAX(0,G4-'M01'!H3)*IF(AND(D4<>0,E4<>0),E4/D4,'M01'!V3),G4*IF(AND(D4<>0,E4<>0),E4/D4,'M01'!V3)) | I4: =IFERROR(H4/G4,0) | J4: =-'M01'!S3 | K4: =E4+H4-N4 | L4: =IFERROR(K4/J4,0) | M4: ='M01'!T3 | N4: ='M01'!U3 | O4: =IFERROR(N4/M4,0) | P4: ='M02'!E3 | Q4: ='M02'!F3 | R4: =IFERROR(Q4/P4,0) | S4: ='M02'!M3 | T4: =IF('M02'!AG3>0,'M02'!AG3+MAX(0,S4-'M02'!H3)*IF(AND(P4<>0,Q4<>0),Q4/P4,'M02'!V3),S4*IF(AND(P4<>0,Q4<>0),Q4/P4,'M02'!V3)) | U4: =IFERROR(T4/S4,0) | V4: =-'M02'!S3 | W4: =Q4+T4-Z4 | X4: =IFERROR(W4/V4,0) | Y4: ='M02'!T3 | Z4: ='M02'!U3 | AA4: =IFERROR(Z4/Y4,0) | AB4: ='M03'!E3 | AC4: ='M03'!F3 | AD4: =IFERROR(AC4/AB4,0) | AE4: ='M03'!M3 | AF4: =IF('M03'!AG3>0,'M03'!AG3+MAX(0,AE4-'M03'!H3)*IF(AND(AB4<>0,AC4<>0),AC4/AB4,'M03'!V3),AE4*IF(AND(AB4<>0,AC4<>0),AC4/AB4,'M03'!V3)) | AG4: =IFERROR(AF4/AE4,0) | AH4: =-'M03'!S3 | AI4: =AC4+AF4-AL4 | AJ4: =IFERROR(AI4/AH4,0) | AK4: ='M03'!T3 | AL4: ='M03'!U3 | AM4: =IFERROR(AL4/AK4,0) | AN4: ='M04'!E3 | AO4: ='M04'!F3 | AP4: =IFERROR(AO4/AN4,0) | AQ4: ='M04'!M3 | AR4: =IF('M04'!AG3>0,'M04'!AG3+MAX(0,AQ4-'M04'!H3)*IF(AND(AN4<>0,AO4<>0),AO4/AN4,'M04'!V3),AQ4*IF(AND(AN4<>0,AO4<>0),AO4/AN4,'M04'!V3)) | AS4: =IFERROR(AR4/AQ4,0) | AT4: =-'M04'!S3 | AU4: =AO4+AR4-AX4 | AV4: =IFERROR(AU4/AT4,0) | AW4: ='M04'!T3 | AX4: ='M04'!U3 | AY4: =IFERROR(AX4/AW4,0) | AZ4: ='M05'!E3 | BA4: ='M05'!F3 | BB4: =IFERROR(BA4/AZ4,0) | BC4: ='M05'!M3 | BD4: =IF('M05'!AG3>0,'M05'!AG3+MAX(0,BC4-'M05'!H3)*IF(AND(AZ4<>0,BA4<>0),BA4/AZ4,'M05'!V3),BC4*IF(AND(AZ4<>0,BA4<>0),BA4/AZ4,'M05'!V3)) | BE4: =IFERROR(BD4/BC4,0) | BF4: =-'M05'!S3 | BG4: =BA4+BD4-BJ4 | BH4: =IFERROR(BG4/BF4,0) | BI4: ='M05'!T3 | BJ4: ='M05'!U3 | BK4: =IFERROR(BJ4/BI4,0) | BL4: ='M06'!E3 | BM4: ='M06'!F3 | BN4: =IFERROR(BM4/BL4,0) | BO4: ='M06'!M3 | BP4: =IF('M06'!AG3>0,'M06'!AG3+MAX(0,BO4-'M06'!H3)*IF(AND(BL4<>0,BM4<>0),BM4/BL4,'M06'!V3),BO4*IF(AND(BL4<>0,BM4<>0),BM4/BL4,'M06'!V3)) | BQ4: =IFERROR(BP4/BO4,0) | BR4: =-'M06'!S3 | BS4: =BM4+BP4-BV4 | BT4: =IFERROR(BS4/BR4,0) | BU4: ='M06'!T3 | BV4: ='M06'!U3 | BW4: =IFERROR(BV4/BU4,0) | BX4: ='M07'!E3 | BY4: ='M07'!F3 | BZ4: =IFERROR(BY4/BX4,0) | CA4: ='M07'!M3 | CB4: =IF('M07'!AG3>0,'M07'!AG3+MAX(0,CA4-'M07'!H3)*IF(AND(BX4<>0,BY4<>0),BY4/BX4,'M07'!V3),CA4*IF(AND(BX4<>0,BY4<>0),BY4/BX4,'M07'!V3)) | CC4: =IFERROR(CB4/CA4,0) | CD4: =-'M07'!S3 | CE4: =BY4+CB4-CH4 | CF4: =IFERROR(CE4/CD4,0) | CG4: ='M07'!T3 | CH4: ='M07'!U3 | CI4: =IFERROR(CH4/CG4,0) | CJ4: ='M08'!E3 | CK4: ='M08'!F3 | CL4: =IFERROR(CK4/CJ4,0) | CM4: ='M08'!M3 | CN4: =IF('M08'!AG3>0,'M08'!AG3+MAX(0,CM4-'M08'!H3)*IF(AND(CJ4<>0,CK4<>0),CK4/CJ4,'M08'!V3),CM4*IF(AND(CJ4<>0,CK4<>0),CK4/CJ4,'M08'!V3)) | CO4: =IFERROR(CN4/CM4,0) | CP4: =-'M08'!S3 | CQ4: =CK4+CN4-CT4 | CR4: =IFERROR(CQ4/CP4,0) | CS4: ='M08'!T3 | CT4: ='M08'!U3 | CU4: =IFERROR(CT4/CS4,0) | CV4: ='M09'!E3 | CW4: ='M09'!F3 | CX4: =IFERROR(CW4/CV4,0) | CY4: ='M09'!M3 | CZ4: =IF('M09'!AG3>0,'M09'!AG3+MAX(0,CY4-'M09'!H3)*IF(AND(CV4<>0,CW4<>0),CW4/CV4,'M09'!V3),CY4*IF(AND(CV4<>0,CW4<>0),CW4/CV4,'M09'!V3)) | DA4: =IFERROR(CZ4/CY4,0) | DB4: =-'M09'!S3 | DC4: =CW4+CZ4-DF4 | DD4: =IFERROR(DC4/DB4,0) | DE4: ='M09'!T3 | DF4: ='M09'!U3 | DG4: =IFERROR(DF4/DE4,0) | DH4: =SUM(J4,V4,AH4,AT4,BF4,BR4,CD4,CP4,DB4) | DI4: =SUM(K4,W4,AI4,AU4,BG4,BS4,CE4,CQ4,DC4) | DJ4: =DH4/9 | DK4: =DI4/9 | DL4: =IFERROR(DI4/DH4,0) | DM4: ='M09'!V3 | DN4: =IFERROR(DL4/DM4-1,0) | DO4: ='M09'!AD3 | DP4: =DJ4-DO4 | DQ4: =COUNTIF(J4,">0")+COUNTIF(V4,">0")+COUNTIF(AH4,">0")+COUNTIF(AT4,">0")+COUNTIF(BF4,">0")+COUNTIF(BR4,">0")+COUNTIF(CD4,">0")+COUNTIF(CP4,">0")+COUNTIF(DB4,">0") | DR4: =DE4 | DS4: =IFERROR(DR4/DJ4,0) | DT4: =D4+SUM(G4,S4,AE4,AQ4,BC4,BO4,CA4,CM4,CY4)-SUM(J4,V4,AH4,AT4,BF4,BR4,CD4,CP4,DB4)-DE4
A5: ='M01'!C4 | B5: ='M01'!D4 | C5: ='M01'!A4 | D5: ='M01'!E4 | E5: ='M01'!F4 | F5: =IFERROR(E5/D5,0) | G5: ='M01'!M4 | H5: =IF('M01'!AG4>0,'M01'!AG4+MAX(0,G5-'M01'!H4)*IF(AND(D5<>0,E5<>0),E5/D5,'M01'!V4),G5*IF(AND(D5<>0,E5<>0),E5/D5,'M01'!V4)) | I5: =IFERROR(H5/G5,0) | J5: =-'M01'!S4 | K5: =E5+H5-N5 | L5: =IFERROR(K5/J5,0) | M5: ='M01'!T4 | N5: ='M01'!U4 | O5: =IFERROR(N5/M5,0) | P5: ='M02'!E4 | Q5: ='M02'!F4 | R5: =IFERROR(Q5/P5,0) | S5: ='M02'!M4 | T5: =IF('M02'!AG4>0,'M02'!AG4+MAX(0,S5-'M02'!H4)*IF(AND(P5<>0,Q5<>0),Q5/P5,'M02'!V4),S5*IF(AND(P5<>0,Q5<>0),Q5/P5,'M02'!V4)) | U5: =IFERROR(T5/S5,0) | V5: =-'M02'!S4 | W5: =Q5+T5-Z5 | X5: =IFERROR(W5/V5,0) | Y5: ='M02'!T4 | Z5: ='M02'!U4 | AA5: =IFERROR(Z5/Y5,0) | AB5: ='M03'!E4 | AC5: ='M03'!F4 | AD5: =IFERROR(AC5/AB5,0) | AE5: ='M03'!M4 | AF5: =IF('M03'!AG4>0,'M03'!AG4+MAX(0,AE5-'M03'!H4)*IF(AND(AB5<>0,AC5<>0),AC5/AB5,'M03'!V4),AE5*IF(AND(AB5<>0,AC5<>0),AC5/AB5,'M03'!V4)) | AG5: =IFERROR(AF5/AE5,0) | AH5: =-'M03'!S4 | AI5: =AC5+AF5-AL5 | AJ5: =IFERROR(AI5/AH5,0) | AK5: ='M03'!T4 | AL5: ='M03'!U4 | AM5: =IFERROR(AL5/AK5,0) | AN5: ='M04'!E4 | AO5: ='M04'!F4 | AP5: =IFERROR(AO5/AN5,0) | AQ5: ='M04'!M4 | AR5: =IF('M04'!AG4>0,'M04'!AG4+MAX(0,AQ5-'M04'!H4)*IF(AND(AN5<>0,AO5<>0),AO5/AN5,'M04'!V4),AQ5*IF(AND(AN5<>0,AO5<>0),AO5/AN5,'M04'!V4)) | AS5: =IFERROR(AR5/AQ5,0) | AT5: =-'M04'!S4 | AU5: =AO5+AR5-AX5 | AV5: =IFERROR(AU5/AT5,0) | AW5: ='M04'!T4 | AX5: ='M04'!U4 | AY5: =IFERROR(AX5/AW5,0) | AZ5: ='M05'!E4 | BA5: ='M05'!F4 | BB5: =IFERROR(BA5/AZ5,0) | BC5: ='M05'!M4 | BD5: =IF('M05'!AG4>0,'M05'!AG4+MAX(0,BC5-'M05'!H4)*IF(AND(AZ5<>0,BA5<>0),BA5/AZ5,'M05'!V4),BC5*IF(AND(AZ5<>0,BA5<>0),BA5/AZ5,'M05'!V4)) | BE5: =IFERROR(BD5/BC5,0) | BF5: =-'M05'!S4 | BG5: =BA5+BD5-BJ5 | BH5: =IFERROR(BG5/BF5,0) | BI5: ='M05'!T4 | BJ5: ='M05'!U4 | BK5: =IFERROR(BJ5/BI5,0) | BL5: ='M06'!E4 | BM5: ='M06'!F4 | BN5: =IFERROR(BM5/BL5,0) | BO5: ='M06'!M4 | BP5: =IF('M06'!AG4>0,'M06'!AG4+MAX(0,BO5-'M06'!H4)*IF(AND(BL5<>0,BM5<>0),BM5/BL5,'M06'!V4),BO5*IF(AND(BL5<>0,BM5<>0),BM5/BL5,'M06'!V4)) | BQ5: =IFERROR(BP5/BO5,0) | BR5: =-'M06'!S4 | BS5: =BM5+BP5-BV5 | BT5: =IFERROR(BS5/BR5,0) | BU5: ='M06'!T4 | BV5: ='M06'!U4 | BW5: =IFERROR(BV5/BU5,0) | BX5: ='M07'!E4 | BY5: ='M07'!F4 | BZ5: =IFERROR(BY5/BX5,0) | CA5: ='M07'!M4 | CB5: =IF('M07'!AG4>0,'M07'!AG4+MAX(0,CA5-'M07'!H4)*IF(AND(BX5<>0,BY5<>0),BY5/BX5,'M07'!V4),CA5*IF(AND(BX5<>0,BY5<>0),BY5/BX5,'M07'!V4)) | CC5: =IFERROR(CB5/CA5,0) | CD5: =-'M07'!S4 | CE5: =BY5+CB5-CH5 | CF5: =IFERROR(CE5/CD5,0) | CG5: ='M07'!T4 | CH5: ='M07'!U4 | CI5: =IFERROR(CH5/CG5,0) | CJ5: ='M08'!E4 | CK5: ='M08'!F4 | CL5: =IFERROR(CK5/CJ5,0) | CM5: ='M08'!M4 | CN5: =IF('M08'!AG4>0,'M08'!AG4+MAX(0,CM5-'M08'!H4)*IF(AND(CJ5<>0,CK5<>0),CK5/CJ5,'M08'!V4),CM5*IF(AND(CJ5<>0,CK5<>0),CK5/CJ5,'M08'!V4)) | CO5: =IFERROR(CN5/CM5,0) | CP5: =-'M08'!S4 | CQ5: =CK5+CN5-CT5 | CR5: =IFERROR(CQ5/CP5,0) | CS5: ='M08'!T4 | CT5: ='M08'!U4 | CU5: =IFERROR(CT5/CS5,0) | CV5: ='M09'!E4 | CW5: ='M09'!F4 | CX5: =IFERROR(CW5/CV5,0) | CY5: ='M09'!M4 | CZ5: =IF('M09'!AG4>0,'M09'!AG4+MAX(0,CY5-'M09'!H4)*IF(AND(CV5<>0,CW5<>0),CW5/CV5,'M09'!V4),CY5*IF(AND(CV5<>0,CW5<>0),CW5/CV5,'M09'!V4)) | DA5: =IFERROR(CZ5/CY5,0) | DB5: =-'M09'!S4 | DC5: =CW5+CZ5-DF5 | DD5: =IFERROR(DC5/DB5,0) | DE5: ='M09'!T4 | DF5: ='M09'!U4 | DG5: =IFERROR(DF5/DE5,0) | DH5: =SUM(J5,V5,AH5,AT5,BF5,BR5,CD5,CP5,DB5) | DI5: =SUM(K5,W5,AI5,AU5,BG5,BS5,CE5,CQ5,DC5) | DJ5: =DH5/9 | DK5: =DI5/9 | DL5: =IFERROR(DI5/DH5,0) | DM5: ='M09'!V4 | DN5: =IFERROR(DL5/DM5-1,0) | DO5: ='M09'!AD4 | DP5: =DJ5-DO5 | DQ5: =COUNTIF(J5,">0")+COUNTIF(V5,">0")+COUNTIF(AH5,">0")+COUNTIF(AT5,">0")+COUNTIF(BF5,">0")+COUNTIF(BR5,">0")+COUNTIF(CD5,">0")+COUNTIF(CP5,">0")+COUNTIF(DB5,">0") | DR5: =DE5 | DS5: =IFERROR(DR5/DJ5,0) | DT5: =D5+SUM(G5,S5,AE5,AQ5,BC5,BO5,CA5,CM5,CY5)-SUM(J5,V5,AH5,AT5,BF5,BR5,CD5,CP5,DB5)-DE5
A6: ='M01'!C5 | B6: ='M01'!D5 | C6: ='M01'!A5 | D6: ='M01'!E5 | E6: ='M01'!F5 | F6: =IFERROR(E6/D6,0) | G6: ='M01'!M5 | H6: =IF('M01'!AG5>0,'M01'!AG5+MAX(0,G6-'M01'!H5)*IF(AND(D6<>0,E6<>0),E6/D6,'M01'!V5),G6*IF(AND(D6<>0,E6<>0),E6/D6,'M01'!V5)) | I6: =IFERROR(H6/G6,0) | J6: =-'M01'!S5 | K6: =E6+H6-N6 | L6: =IFERROR(K6/J6,0) | M6: ='M01'!T5 | N6: ='M01'!U5 | O6: =IFERROR(N6/M6,0) | P6: ='M02'!E5 | Q6: ='M02'!F5 | R6: =IFERROR(Q6/P6,0) | S6: ='M02'!M5 | T6: =IF('M02'!AG5>0,'M02'!AG5+MAX(0,S6-'M02'!H5)*IF(AND(P6<>0,Q6<>0),Q6/P6,'M02'!V5),S6*IF(AND(P6<>0,Q6<>0),Q6/P6,'M02'!V5)) | U6: =IFERROR(T6/S6,0) | V6: =-'M02'!S5 | W6: =Q6+T6-Z6 | X6: =IFERROR(W6/V6,0) | Y6: ='M02'!T5 | Z6: ='M02'!U5 | AA6: =IFERROR(Z6/Y6,0) | AB6: ='M03'!E5 | AC6: ='M03'!F5 | AD6: =IFERROR(AC6/AB6,0) | AE6: ='M03'!M5 | AF6: =IF('M03'!AG5>0,'M03'!AG5+MAX(0,AE6-'M03'!H5)*IF(AND(AB6<>0,AC6<>0),AC6/AB6,'M03'!V5),AE6*IF(AND(AB6<>0,AC6<>0),AC6/AB6,'M03'!V5)) | AG6: =IFERROR(AF6/AE6,0) | AH6: =-'M03'!S5 | AI6: =AC6+AF6-AL6 | AJ6: =IFERROR(AI6/AH6,0) | AK6: ='M03'!T5 | AL6: ='M03'!U5 | AM6: =IFERROR(AL6/AK6,0) | AN6: ='M04'!E5 | AO6: ='M04'!F5 | AP6: =IFERROR(AO6/AN6,0) | AQ6: ='M04'!M5 | AR6: =IF('M04'!AG5>0,'M04'!AG5+MAX(0,AQ6-'M04'!H5)*IF(AND(AN6<>0,AO6<>0),AO6/AN6,'M04'!V5),AQ6*IF(AND(AN6<>0,AO6<>0),AO6/AN6,'M04'!V5)) | AS6: =IFERROR(AR6/AQ6,0) | AT6: =-'M04'!S5 | AU6: =AO6+AR6-AX6 | AV6: =IFERROR(AU6/AT6,0) | AW6: ='M04'!T5 | AX6: ='M04'!U5 | AY6: =IFERROR(AX6/AW6,0) | AZ6: ='M05'!E5 | BA6: ='M05'!F5 | BB6: =IFERROR(BA6/AZ6,0) | BC6: ='M05'!M5 | BD6: =IF('M05'!AG5>0,'M05'!AG5+MAX(0,BC6-'M05'!H5)*IF(AND(AZ6<>0,BA6<>0),BA6/AZ6,'M05'!V5),BC6*IF(AND(AZ6<>0,BA6<>0),BA6/AZ6,'M05'!V5)) | BE6: =IFERROR(BD6/BC6,0) | BF6: =-'M05'!S5 | BG6: =BA6+BD6-BJ6 | BH6: =IFERROR(BG6/BF6,0) | BI6: ='M05'!T5 | BJ6: ='M05'!U5 | BK6: =IFERROR(BJ6/BI6,0) | BL6: ='M06'!E5 | BM6: ='M06'!F5 | BN6: =IFERROR(BM6/BL6,0) | BO6: ='M06'!M5 | BP6: =IF('M06'!AG5>0,'M06'!AG5+MAX(0,BO6-'M06'!H5)*IF(AND(BL6<>0,BM6<>0),BM6/BL6,'M06'!V5),BO6*IF(AND(BL6<>0,BM6<>0),BM6/BL6,'M06'!V5)) | BQ6: =IFERROR(BP6/BO6,0) | BR6: =-'M06'!S5 | BS6: =BM6+BP6-BV6 | BT6: =IFERROR(BS6/BR6,0) | BU6: ='M06'!T5 | BV6: ='M06'!U5 | BW6: =IFERROR(BV6/BU6,0) | BX6: ='M07'!E5 | BY6: ='M07'!F5 | BZ6: =IFERROR(BY6/BX6,0) | CA6: ='M07'!M5 | CB6: =IF('M07'!AG5>0,'M07'!AG5+MAX(0,CA6-'M07'!H5)*IF(AND(BX6<>0,BY6<>0),BY6/BX6,'M07'!V5),CA6*IF(AND(BX6<>0,BY6<>0),BY6/BX6,'M07'!V5)) | CC6: =IFERROR(CB6/CA6,0) | CD6: =-'M07'!S5 | CE6: =BY6+CB6-CH6 | CF6: =IFERROR(CE6/CD6,0) | CG6: ='M07'!T5 | CH6: ='M07'!U5 | CI6: =IFERROR(CH6/CG6,0) | CJ6: ='M08'!E5 | CK6: ='M08'!F5 | CL6: =IFERROR(CK6/CJ6,0) | CM6: ='M08'!M5 | CN6: =IF('M08'!AG5>0,'M08'!AG5+MAX(0,CM6-'M08'!H5)*IF(AND(CJ6<>0,CK6<>0),CK6/CJ6,'M08'!V5),CM6*IF(AND(CJ6<>0,CK6<>0),CK6/CJ6,'M08'!V5)) | CO6: =IFERROR(CN6/CM6,0) | CP6: =-'M08'!S5 | CQ6: =CK6+CN6-CT6 | CR6: =IFERROR(CQ6/CP6,0) | CS6: ='M08'!T5 | CT6: ='M08'!U5 | CU6: =IFERROR(CT6/CS6,0) | CV6: ='M09'!E5 | CW6: ='M09'!F5 | CX6: =IFERROR(CW6/CV6,0) | CY6: ='M09'!M5 | CZ6: =IF('M09'!AG5>0,'M09'!AG5+MAX(0,CY6-'M09'!H5)*IF(AND(CV6<>0,CW6<>0),CW6/CV6,'M09'!V5),CY6*IF(AND(CV6<>0,CW6<>0),CW6/CV6,'M09'!V5)) | DA6: =IFERROR(CZ6/CY6,0) | DB6: =-'M09'!S5 | DC6: =CW6+CZ6-DF6 | DD6: =IFERROR(DC6/DB6,0) | DE6: ='M09'!T5 | DF6: ='M09'!U5 | DG6: =IFERROR(DF6/DE6,0) | DH6: =SUM(J6,V6,AH6,AT6,BF6,BR6,CD6,CP6,DB6) | DI6: =SUM(K6,W6,AI6,AU6,BG6,BS6,CE6,CQ6,DC6) | DJ6: =DH6/9 | DK6: =DI6/9 | DL6: =IFERROR(DI6/DH6,0) | DM6: ='M09'!V5 | DN6: =IFERROR(DL6/DM6-1,0) | DO6: ='M09'!AD5 | DP6: =DJ6-DO6 | DQ6: =COUNTIF(J6,">0")+COUNTIF(V6,">0")+COUNTIF(AH6,">0")+COUNTIF(AT6,">0")+COUNTIF(BF6,">0")+COUNTIF(BR6,">0")+COUNTIF(CD6,">0")+COUNTIF(CP6,">0")+COUNTIF(DB6,">0") | DR6: =DE6 | DS6: =IFERROR(DR6/DJ6,0) | DT6: =D6+SUM(G6,S6,AE6,AQ6,BC6,BO6,CA6,CM6,CY6)-SUM(J6,V6,AH6,AT6,BF6,BR6,CD6,CP6,DB6)-DE6
A7: ='M01'!C6 | B7: ='M01'!D6 | C7: ='M01'!A6 | D7: ='M01'!E6 | E7: ='M01'!F6 | F7: =IFERROR(E7/D7,0) | G7: ='M01'!M6 | H7: =IF('M01'!AG6>0,'M01'!AG6+MAX(0,G7-'M01'!H6)*IF(AND(D7<>0,E7<>0),E7/D7,'M01'!V6),G7*IF(AND(D7<>0,E7<>0),E7/D7,'M01'!V6)) | I7: =IFERROR(H7/G7,0) | J7: =-'M01'!S6 | K7: =E7+H7-N7 | L7: =IFERROR(K7/J7,0) | M7: ='M01'!T6 | N7: ='M01'!U6 | O7: =IFERROR(N7/M7,0) | P7: ='M02'!E6 | Q7: ='M02'!F6 | R7: =IFERROR(Q7/P7,0) | S7: ='M02'!M6 | T7: =IF('M02'!AG6>0,'M02'!AG6+MAX(0,S7-'M02'!H6)*IF(AND(P7<>0,Q7<>0),Q7/P7,'M02'!V6),S7*IF(AND(P7<>0,Q7<>0),Q7/P7,'M02'!V6)) | U7: =IFERROR(T7/S7,0) | V7: =-'M02'!S6 | W7: =Q7+T7-Z7 | X7: =IFERROR(W7/V7,0) | Y7: ='M02'!T6 | Z7: ='M02'!U6 | AA7: =IFERROR(Z7/Y7,0) | AB7: ='M03'!E6 | AC7: ='M03'!F6 | AD7: =IFERROR(AC7/AB7,0) | AE7: ='M03'!M6 | AF7: =IF('M03'!AG6>0,'M03'!AG6+MAX(0,AE7-'M03'!H6)*IF(AND(AB7<>0,AC7<>0),AC7/AB7,'M03'!V6),AE7*IF(AND(AB7<>0,AC7<>0),AC7/AB7,'M03'!V6)) | AG7: =IFERROR(AF7/AE7,0) | AH7: =-'M03'!S6 | AI7: =AC7+AF7-AL7 | AJ7: =IFERROR(AI7/AH7,0) | AK7: ='M03'!T6 | AL7: ='M03'!U6 | AM7: =IFERROR(AL7/AK7,0) | AN7: ='M04'!E6 | AO7: ='M04'!F6 | AP7: =IFERROR(AO7/AN7,0) | AQ7: ='M04'!M6 | AR7: =IF('M04'!AG6>0,'M04'!AG6+MAX(0,AQ7-'M04'!H6)*IF(AND(AN7<>0,AO7<>0),AO7/AN7,'M04'!V6),AQ7*IF(AND(AN7<>0,AO7<>0),AO7/AN7,'M04'!V6)) | AS7: =IFERROR(AR7/AQ7,0) | AT7: =-'M04'!S6 | AU7: =AO7+AR7-AX7 | AV7: =IFERROR(AU7/AT7,0) | AW7: ='M04'!T6 | AX7: ='M04'!U6 | AY7: =IFERROR(AX7/AW7,0) | AZ7: ='M05'!E6 | BA7: ='M05'!F6 | BB7: =IFERROR(BA7/AZ7,0) | BC7: ='M05'!M6 | BD7: =IF('M05'!AG6>0,'M05'!AG6+MAX(0,BC7-'M05'!H6)*IF(AND(AZ7<>0,BA7<>0),BA7/AZ7,'M05'!V6),BC7*IF(AND(AZ7<>0,BA7<>0),BA7/AZ7,'M05'!V6)) | BE7: =IFERROR(BD7/BC7,0) | BF7: =-'M05'!S6 | BG7: =BA7+BD7-BJ7 | BH7: =IFERROR(BG7/BF7,0) | BI7: ='M05'!T6 | BJ7: ='M05'!U6 | BK7: =IFERROR(BJ7/BI7,0) | BL7: ='M06'!E6 | BM7: ='M06'!F6 | BN7: =IFERROR(BM7/BL7,0) | BO7: ='M06'!M6 | BP7: =IF('M06'!AG6>0,'M06'!AG6+MAX(0,BO7-'M06'!H6)*IF(AND(BL7<>0,BM7<>0),BM7/BL7,'M06'!V6),BO7*IF(AND(BL7<>0,BM7<>0),BM7/BL7,'M06'!V6)) | BQ7: =IFERROR(BP7/BO7,0) | BR7: =-'M06'!S6 | BS7: =BM7+BP7-BV7 | BT7: =IFERROR(BS7/BR7,0) | BU7: ='M06'!T6 | BV7: ='M06'!U6 | BW7: =IFERROR(BV7/BU7,0) | BX7: ='M07'!E6 | BY7: ='M07'!F6 | BZ7: =IFERROR(BY7/BX7,0) | CA7: ='M07'!M6 | CB7: =IF('M07'!AG6>0,'M07'!AG6+MAX(0,CA7-'M07'!H6)*IF(AND(BX7<>0,BY7<>0),BY7/BX7,'M07'!V6),CA7*IF(AND(BX7<>0,BY7<>0),BY7/BX7,'M07'!V6)) | CC7: =IFERROR(CB7/CA7,0) | CD7: =-'M07'!S6 | CE7: =BY7+CB7-CH7 | CF7: =IFERROR(CE7/CD7,0) | CG7: ='M07'!T6 | CH7: ='M07'!U6 | CI7: =IFERROR(CH7/CG7,0) | CJ7: ='M08'!E6 | CK7: ='M08'!F6 | CL7: =IFERROR(CK7/CJ7,0) | CM7: ='M08'!M6 | CN7: =IF('M08'!AG6>0,'M08'!AG6+MAX(0,CM7-'M08'!H6)*IF(AND(CJ7<>0,CK7<>0),CK7/CJ7,'M08'!V6),CM7*IF(AND(CJ7<>0,CK7<>0),CK7/CJ7,'M08'!V6)) | CO7: =IFERROR(CN7/CM7,0) | CP7: =-'M08'!S6 | CQ7: =CK7+CN7-CT7 | CR7: =IFERROR(CQ7/CP7,0) | CS7: ='M08'!T6 | CT7: ='M08'!U6 | CU7: =IFERROR(CT7/CS7,0) | CV7: ='M09'!E6 | CW7: ='M09'!F6 | CX7: =IFERROR(CW7/CV7,0) | CY7: ='M09'!M6 | CZ7: =IF('M09'!AG6>0,'M09'!AG6+MAX(0,CY7-'M09'!H6)*IF(AND(CV7<>0,CW7<>0),CW7/CV7,'M09'!V6),CY7*IF(AND(CV7<>0,CW7<>0),CW7/CV7,'M09'!V6)) | DA7: =IFERROR(CZ7/CY7,0) | DB7: =-'M09'!S6 | DC7: =CW7+CZ7-DF7 | DD7: =IFERROR(DC7/DB7,0) | DE7: ='M09'!T6 | DF7: ='M09'!U6 | DG7: =IFERROR(DF7/DE7,0) | DH7: =SUM(J7,V7,AH7,AT7,BF7,BR7,CD7,CP7,DB7) | DI7: =SUM(K7,W7,AI7,AU7,BG7,BS7,CE7,CQ7,DC7) | DJ7: =DH7/9 | DK7: =DI7/9 | DL7: =IFERROR(DI7/DH7,0) | DM7: ='M09'!V6 | DN7: =IFERROR(DL7/DM7-1,0) | DO7: ='M09'!AD6 | DP7: =DJ7-DO7 | DQ7: =COUNTIF(J7,">0")+COUNTIF(V7,">0")+COUNTIF(AH7,">0")+COUNTIF(AT7,">0")+COUNTIF(BF7,">0")+COUNTIF(BR7,">0")+COUNTIF(CD7,">0")+COUNTIF(CP7,">0")+COUNTIF(DB7,">0") | DR7: =DE7 | DS7: =IFERROR(DR7/DJ7,0) | DT7: =D7+SUM(G7,S7,AE7,AQ7,BC7,BO7,CA7,CM7,CY7)-SUM(J7,V7,AH7,AT7,BF7,BR7,CD7,CP7,DB7)-DE7
A8: ='M01'!C7 | B8: ='M01'!D7 | C8: ='M01'!A7 | D8: ='M01'!E7 | E8: ='M01'!F7 | F8: =IFERROR(E8/D8,0) | G8: ='M01'!M7 | H8: =IF('M01'!AG7>0,'M01'!AG7+MAX(0,G8-'M01'!H7)*IF(AND(D8<>0,E8<>0),E8/D8,'M01'!V7),G8*IF(AND(D8<>0,E8<>0),E8/D8,'M01'!V7)) | I8: =IFERROR(H8/G8,0) | J8: =-'M01'!S7 | K8: =E8+H8-N8 | L8: =IFERROR(K8/J8,0) | M8: ='M01'!T7 | N8: ='M01'!U7 | O8: =IFERROR(N8/M8,0) | P8: ='M02'!E7 | Q8: ='M02'!F7 | R8: =IFERROR(Q8/P8,0) | S8: ='M02'!M7 | T8: =IF('M02'!AG7>0,'M02'!AG7+MAX(0,S8-'M02'!H7)*IF(AND(P8<>0,Q8<>0),Q8/P8,'M02'!V7),S8*IF(AND(P8<>0,Q8<>0),Q8/P8,'M02'!V7)) | U8: =IFERROR(T8/S8,0) | V8: =-'M02'!S7 | W8: =Q8+T8-Z8 | X8: =IFERROR(W8/V8,0) | Y8: ='M02'!T7 | Z8: ='M02'!U7 | AA8: =IFERROR(Z8/Y8,0) | AB8: ='M03'!E7 | AC8: ='M03'!F7 | AD8: =IFERROR(AC8/AB8,0) | AE8: ='M03'!M7 | AF8: =IF('M03'!AG7>0,'M03'!AG7+MAX(0,AE8-'M03'!H7)*IF(AND(AB8<>0,AC8<>0),AC8/AB8,'M03'!V7),AE8*IF(AND(AB8<>0,AC8<>0),AC8/AB8,'M03'!V7)) | AG8: =IFERROR(AF8/AE8,0) | AH8: =-'M03'!S7 | AI8: =AC8+AF8-AL8 | AJ8: =IFERROR(AI8/AH8,0) | AK8: ='M03'!T7 | AL8: ='M03'!U7 | AM8: =IFERROR(AL8/AK8,0) | AN8: ='M04'!E7 | AO8: ='M04'!F7 | AP8: =IFERROR(AO8/AN8,0) | AQ8: ='M04'!M7 | AR8: =IF('M04'!AG7>0,'M04'!AG7+MAX(0,AQ8-'M04'!H7)*IF(AND(AN8<>0,AO8<>0),AO8/AN8,'M04'!V7),AQ8*IF(AND(AN8<>0,AO8<>0),AO8/AN8,'M04'!V7)) | AS8: =IFERROR(AR8/AQ8,0) | AT8: =-'M04'!S7 | AU8: =AO8+AR8-AX8 | AV8: =IFERROR(AU8/AT8,0) | AW8: ='M04'!T7 | AX8: ='M04'!U7 | AY8: =IFERROR(AX8/AW8,0) | AZ8: ='M05'!E7 | BA8: ='M05'!F7 | BB8: =IFERROR(BA8/AZ8,0) | BC8: ='M05'!M7 | BD8: =IF('M05'!AG7>0,'M05'!AG7+MAX(0,BC8-'M05'!H7)*IF(AND(AZ8<>0,BA8<>0),BA8/AZ8,'M05'!V7),BC8*IF(AND(AZ8<>0,BA8<>0),BA8/AZ8,'M05'!V7)) | BE8: =IFERROR(BD8/BC8,0) | BF8: =-'M05'!S7 | BG8: =BA8+BD8-BJ8 | BH8: =IFERROR(BG8/BF8,0) | BI8: ='M05'!T7 | BJ8: ='M05'!U7 | BK8: =IFERROR(BJ8/BI8,0) | BL8: ='M06'!E7 | BM8: ='M06'!F7 | BN8: =IFERROR(BM8/BL8,0) | BO8: ='M06'!M7 | BP8: =IF('M06'!AG7>0,'M06'!AG7+MAX(0,BO8-'M06'!H7)*IF(AND(BL8<>0,BM8<>0),BM8/BL8,'M06'!V7),BO8*IF(AND(BL8<>0,BM8<>0),BM8/BL8,'M06'!V7)) | BQ8: =IFERROR(BP8/BO8,0) | BR8: =-'M06'!S7 | BS8: =BM8+BP8-BV8 | BT8: =IFERROR(BS8/BR8,0) | BU8: ='M06'!T7 | BV8: ='M06'!U7 | BW8: =IFERROR(BV8/BU8,0) | BX8: ='M07'!E7 | BY8: ='M07'!F7 | BZ8: =IFERROR(BY8/BX8,0) | CA8: ='M07'!M7 | CB8: =IF('M07'!AG7>0,'M07'!AG7+MAX(0,CA8-'M07'!H7)*IF(AND(BX8<>0,BY8<>0),BY8/BX8,'M07'!V7),CA8*IF(AND(BX8<>0,BY8<>0),BY8/BX8,'M07'!V7)) | CC8: =IFERROR(CB8/CA8,0) | CD8: =-'M07'!S7 | CE8: =BY8+CB8-CH8 | CF8: =IFERROR(CE8/CD8,0) | CG8: ='M07'!T7 | CH8: ='M07'!U7 | CI8: =IFERROR(CH8/CG8,0) | CJ8: ='M08'!E7 | CK8: ='M08'!F7 | CL8: =IFERROR(CK8/CJ8,0) | CM8: ='M08'!M7 | CN8: =IF('M08'!AG7>0,'M08'!AG7+MAX(0,CM8-'M08'!H7)*IF(AND(CJ8<>0,CK8<>0),CK8/CJ8,'M08'!V7),CM8*IF(AND(CJ8<>0,CK8<>0),CK8/CJ8,'M08'!V7)) | CO8: =IFERROR(CN8/CM8,0) | CP8: =-'M08'!S7 | CQ8: =CK8+CN8-CT8 | CR8: =IFERROR(CQ8/CP8,0) | CS8: ='M08'!T7 | CT8: ='M08'!U7 | CU8: =IFERROR(CT8/CS8,0) | CV8: ='M09'!E7 | CW8: ='M09'!F7 | CX8: =IFERROR(CW8/CV8,0) | CY8: ='M09'!M7 | CZ8: =IF('M09'!AG7>0,'M09'!AG7+MAX(0,CY8-'M09'!H7)*IF(AND(CV8<>0,CW8<>0),CW8/CV8,'M09'!V7),CY8*IF(AND(CV8<>0,CW8<>0),CW8/CV8,'M09'!V7)) | DA8: =IFERROR(CZ8/CY8,0) | DB8: =-'M09'!S7 | DC8: =CW8+CZ8-DF8 | DD8: =IFERROR(DC8/DB8,0) | DE8: ='M09'!T7 | DF8: ='M09'!U7 | DG8: =IFERROR(DF8/DE8,0) | DH8: =SUM(J8,V8,AH8,AT8,BF8,BR8,CD8,CP8,DB8) | DI8: =SUM(K8,W8,AI8,AU8,BG8,BS8,CE8,CQ8,DC8) | DJ8: =DH8/9 | DK8: =DI8/9 | DL8: =IFERROR(DI8/DH8,0) | DM8: ='M09'!V7 | DN8: =IFERROR(DL8/DM8-1,0) | DO8: ='M09'!AD7 | DP8: =DJ8-DO8 | DQ8: =COUNTIF(J8,">0")+COUNTIF(V8,">0")+COUNTIF(AH8,">0")+COUNTIF(AT8,">0")+COUNTIF(BF8,">0")+COUNTIF(BR8,">0")+COUNTIF(CD8,">0")+COUNTIF(CP8,">0")+COUNTIF(DB8,">0") | DR8: =DE8 | DS8: =IFERROR(DR8/DJ8,0) | DT8: =D8+SUM(G8,S8,AE8,AQ8,BC8,BO8,CA8,CM8,CY8)-SUM(J8,V8,AH8,AT8,BF8,BR8,CD8,CP8,DB8)-DE8
A9: ='M01'!C8 | B9: ='M01'!D8 | C9: ='M01'!A8 | D9: ='M01'!E8 | E9: ='M01'!F8 | F9: =IFERROR(E9/D9,0) | G9: ='M01'!M8 | H9: =IF('M01'!AG8>0,'M01'!AG8+MAX(0,G9-'M01'!H8)*IF(AND(D9<>0,E9<>0),E9/D9,'M01'!V8),G9*IF(AND(D9<>0,E9<>0),E9/D9,'M01'!V8)) | I9: =IFERROR(H9/G9,0) | J9: =-'M01'!S8 | K9: =E9+H9-N9 | L9: =IFERROR(K9/J9,0) | M9: ='M01'!T8 | N9: ='M01'!U8 | O9: =IFERROR(N9/M9,0) | P9: ='M02'!E8 | Q9: ='M02'!F8 | R9: =IFERROR(Q9/P9,0) | S9: ='M02'!M8 | T9: =IF('M02'!AG8>0,'M02'!AG8+MAX(0,S9-'M02'!H8)*IF(AND(P9<>0,Q9<>0),Q9/P9,'M02'!V8),S9*IF(AND(P9<>0,Q9<>0),Q9/P9,'M02'!V8)) | U9: =IFERROR(T9/S9,0) | V9: =-'M02'!S8 | W9: =Q9+T9-Z9 | X9: =IFERROR(W9/V9,0) | Y9: ='M02'!T8 | Z9: ='M02'!U8 | AA9: =IFERROR(Z9/Y9,0) | AB9: ='M03'!E8 | AC9: ='M03'!F8 | AD9: =IFERROR(AC9/AB9,0) | AE9: ='M03'!M8 | AF9: =IF('M03'!AG8>0,'M03'!AG8+MAX(0,AE9-'M03'!H8)*IF(AND(AB9<>0,AC9<>0),AC9/AB9,'M03'!V8),AE9*IF(AND(AB9<>0,AC9<>0),AC9/AB9,'M03'!V8)) | AG9: =IFERROR(AF9/AE9,0) | AH9: =-'M03'!S8 | AI9: =AC9+AF9-AL9 | AJ9: =IFERROR(AI9/AH9,0) | AK9: ='M03'!T8 | AL9: ='M03'!U8 | AM9: =IFERROR(AL9/AK9,0) | AN9: ='M04'!E8 | AO9: ='M04'!F8 | AP9: =IFERROR(AO9/AN9,0) | AQ9: ='M04'!M8 | AR9: =IF('M04'!AG8>0,'M04'!AG8+MAX(0,AQ9-'M04'!H8)*IF(AND(AN9<>0,AO9<>0),AO9/AN9,'M04'!V8),AQ9*IF(AND(AN9<>0,AO9<>0),AO9/AN9,'M04'!V8)) | AS9: =IFERROR(AR9/AQ9,0) | AT9: =-'M04'!S8 | AU9: =AO9+AR9-AX9 | AV9: =IFERROR(AU9/AT9,0) | AW9: ='M04'!T8 | AX9: ='M04'!U8 | AY9: =IFERROR(AX9/AW9,0) | AZ9: ='M05'!E8 | BA9: ='M05'!F8 | BB9: =IFERROR(BA9/AZ9,0) | BC9: ='M05'!M8 | BD9: =IF('M05'!AG8>0,'M05'!AG8+MAX(0,BC9-'M05'!H8)*IF(AND(AZ9<>0,BA9<>0),BA9/AZ9,'M05'!V8),BC9*IF(AND(AZ9<>0,BA9<>0),BA9/AZ9,'M05'!V8)) | BE9: =IFERROR(BD9/BC9,0) | BF9: =-'M05'!S8 | BG9: =BA9+BD9-BJ9 | BH9: =IFERROR(BG9/BF9,0) | BI9: ='M05'!T8 | BJ9: ='M05'!U8 | BK9: =IFERROR(BJ9/BI9,0) | BL9: ='M06'!E8 | BM9: ='M06'!F8 | BN9: =IFERROR(BM9/BL9,0) | BO9: ='M06'!M8 | BP9: =IF('M06'!AG8>0,'M06'!AG8+MAX(0,BO9-'M06'!H8)*IF(AND(BL9<>0,BM9<>0),BM9/BL9,'M06'!V8),BO9*IF(AND(BL9<>0,BM9<>0),BM9/BL9,'M06'!V8)) | BQ9: =IFERROR(BP9/BO9,0) | BR9: =-'M06'!S8 | BS9: =BM9+BP9-BV9 | BT9: =IFERROR(BS9/BR9,0) | BU9: ='M06'!T8 | BV9: ='M06'!U8 | BW9: =IFERROR(BV9/BU9,0) | BX9: ='M07'!E8 | BY9: ='M07'!F8 | BZ9: =IFERROR(BY9/BX9,0) | CA9: ='M07'!M8 | CB9: =IF('M07'!AG8>0,'M07'!AG8+MAX(0,CA9-'M07'!H8)*IF(AND(BX9<>0,BY9<>0),BY9/BX9,'M07'!V8),CA9*IF(AND(BX9<>0,BY9<>0),BY9/BX9,'M07'!V8)) | CC9: =IFERROR(CB9/CA9,0) | CD9: =-'M07'!S8 | CE9: =BY9+CB9-CH9 | CF9: =IFERROR(CE9/CD9,0) | CG9: ='M07'!T8 | CH9: ='M07'!U8 | CI9: =IFERROR(CH9/CG9,0) | CJ9: ='M08'!E8 | CK9: ='M08'!F8 | CL9: =IFERROR(CK9/CJ9,0) | CM9: ='M08'!M8 | CN9: =IF('M08'!AG8>0,'M08'!AG8+MAX(0,CM9-'M08'!H8)*IF(AND(CJ9<>0,CK9<>0),CK9/CJ9,'M08'!V8),CM9*IF(AND(CJ9<>0,CK9<>0),CK9/CJ9,'M08'!V8)) | CO9: =IFERROR(CN9/CM9,0) | CP9: =-'M08'!S8 | CQ9: =CK9+CN9-CT9 | CR9: =IFERROR(CQ9/CP9,0) | CS9: ='M08'!T8 | CT9: ='M08'!U8 | CU9: =IFERROR(CT9/CS9,0) | CV9: ='M09'!E8 | CW9: ='M09'!F8 | CX9: =IFERROR(CW9/CV9,0) | CY9: ='M09'!M8 | CZ9: =IF('M09'!AG8>0,'M09'!AG8+MAX(0,CY9-'M09'!H8)*IF(AND(CV9<>0,CW9<>0),CW9/CV9,'M09'!V8),CY9*IF(AND(CV9<>0,CW9<>0),CW9/CV9,'M09'!V8)) | DA9: =IFERROR(CZ9/CY9,0) | DB9: =-'M09'!S8 | DC9: =CW9+CZ9-DF9 | DD9: =IFERROR(DC9/DB9,0) | DE9: ='M09'!T8 | DF9: ='M09'!U8 | DG9: =IFERROR(DF9/DE9,0) | DH9: =SUM(J9,V9,AH9,AT9,BF9,BR9,CD9,CP9,DB9) | DI9: =SUM(K9,W9,AI9,AU9,BG9,BS9,CE9,CQ9,DC9) | DJ9: =DH9/9 | DK9: =DI9/9 | DL9: =IFERROR(DI9/DH9,0) | DM9: ='M09'!V8 | DN9: =IFERROR(DL9/DM9-1,0) | DO9: ='M09'!AD8 | DP9: =DJ9-DO9 | DQ9: =COUNTIF(J9,">0")+COUNTIF(V9,">0")+COUNTIF(AH9,">0")+COUNTIF(AT9,">0")+COUNTIF(BF9,">0")+COUNTIF(BR9,">0")+COUNTIF(CD9,">0")+COUNTIF(CP9,">0")+COUNTIF(DB9,">0") | DR9: =DE9 | DS9: =IFERROR(DR9/DJ9,0) | DT9: =D9+SUM(G9,S9,AE9,AQ9,BC9,BO9,CA9,CM9,CY9)-SUM(J9,V9,AH9,AT9,BF9,BR9,CD9,CP9,DB9)-DE9
A10: ='M01'!C9 | B10: ='M01'!D9 | C10: ='M01'!A9 | D10: ='M01'!E9 | E10: ='M01'!F9 | F10: =IFERROR(E10/D10,0) | G10: ='M01'!M9 | H10: =IF('M01'!AG9>0,'M01'!AG9+MAX(0,G10-'M01'!H9)*IF(AND(D10<>0,E10<>0),E10/D10,'M01'!V9),G10*IF(AND(D10<>0,E10<>0),E10/D10,'M01'!V9)) | I10: =IFERROR(H10/G10,0) | J10: =-'M01'!S9 | K10: =E10+H10-N10 | L10: =IFERROR(K10/J10,0) | M10: ='M01'!T9 | N10: ='M01'!U9 | O10: =IFERROR(N10/M10,0) | P10: ='M02'!E9 | Q10: ='M02'!F9 | R10: =IFERROR(Q10/P10,0) | S10: ='M02'!M9 | T10: =IF('M02'!AG9>0,'M02'!AG9+MAX(0,S10-'M02'!H9)*IF(AND(P10<>0,Q10<>0),Q10/P10,'M02'!V9),S10*IF(AND(P10<>0,Q10<>0),Q10/P10,'M02'!V9)) | U10: =IFERROR(T10/S10,0) | V10: =-'M02'!S9 | W10: =Q10+T10-Z10 | X10: =IFERROR(W10/V10,0) | Y10: ='M02'!T9 | Z10: ='M02'!U9 | AA10: =IFERROR(Z10/Y10,0) | AB10: ='M03'!E9 | AC10: ='M03'!F9 | AD10: =IFERROR(AC10/AB10,0) | AE10: ='M03'!M9 | AF10: =IF('M03'!AG9>0,'M03'!AG9+MAX(0,AE10-'M03'!H9)*IF(AND(AB10<>0,AC10<>0),AC10/AB10,'M03'!V9),AE10*IF(AND(AB10<>0,AC10<>0),AC10/AB10,'M03'!V9)) | AG10: =IFERROR(AF10/AE10,0) | AH10: =-'M03'!S9 | AI10: =AC10+AF10-AL10 | AJ10: =IFERROR(AI10/AH10,0) | AK10: ='M03'!T9 | AL10: ='M03'!U9 | AM10: =IFERROR(AL10/AK10,0) | AN10: ='M04'!E9 | AO10: ='M04'!F9 | AP10: =IFERROR(AO10/AN10,0) | AQ10: ='M04'!M9 | AR10: =IF('M04'!AG9>0,'M04'!AG9+MAX(0,AQ10-'M04'!H9)*IF(AND(AN10<>0,AO10<>0),AO10/AN10,'M04'!V9),AQ10*IF(AND(AN10<>0,AO10<>0),AO10/AN10,'M04'!V9)) | AS10: =IFERROR(AR10/AQ10,0) | AT10: =-'M04'!S9 | AU10: =AO10+AR10-AX10 | AV10: =IFERROR(AU10/AT10,0) | AW10: ='M04'!T9 | AX10: ='M04'!U9 | AY10: =IFERROR(AX10/AW10,0) | AZ10: ='M05'!E9 | BA10: ='M05'!F9 | BB10: =IFERROR(BA10/AZ10,0) | BC10: ='M05'!M9 | BD10: =IF('M05'!AG9>0,'M05'!AG9+MAX(0,BC10-'M05'!H9)*IF(AND(AZ10<>0,BA10<>0),BA10/AZ10,'M05'!V9),BC10*IF(AND(AZ10<>0,BA10<>0),BA10/AZ10,'M05'!V9)) | BE10: =IFERROR(BD10/BC10,0) | BF10: =-'M05'!S9 | BG10: =BA10+BD10-BJ10 | BH10: =IFERROR(BG10/BF10,0) | BI10: ='M05'!T9 | BJ10: ='M05'!U9 | BK10: =IFERROR(BJ10/BI10,0) | BL10: ='M06'!E9 | BM10: ='M06'!F9 | BN10: =IFERROR(BM10/BL10,0) | BO10: ='M06'!M9 | BP10: =IF('M06'!AG9>0,'M06'!AG9+MAX(0,BO10-'M06'!H9)*IF(AND(BL10<>0,BM10<>0),BM10/BL10,'M06'!V9),BO10*IF(AND(BL10<>0,BM10<>0),BM10/BL10,'M06'!V9)) | BQ10: =IFERROR(BP10/BO10,0) | BR10: =-'M06'!S9 | BS10: =BM10+BP10-BV10 | BT10: =IFERROR(BS10/BR10,0) | BU10: ='M06'!T9 | BV10: ='M06'!U9 | BW10: =IFERROR(BV10/BU10,0) | BX10: ='M07'!E9 | BY10: ='M07'!F9 | BZ10: =IFERROR(BY10/BX10,0) | CA10: ='M07'!M9 | CB10: =IF('M07'!AG9>0,'M07'!AG9+MAX(0,CA10-'M07'!H9)*IF(AND(BX10<>0,BY10<>0),BY10/BX10,'M07'!V9),CA10*IF(AND(BX10<>0,BY10<>0),BY10/BX10,'M07'!V9)) | CC10: =IFERROR(CB10/CA10,0) | CD10: =-'M07'!S9 | CE10: =BY10+CB10-CH10 | CF10: =IFERROR(CE10/CD10,0) | CG10: ='M07'!T9 | CH10: ='M07'!U9 | CI10: =IFERROR(CH10/CG10,0) | CJ10: ='M08'!E9 | CK10: ='M08'!F9 | CL10: =IFERROR(CK10/CJ10,0) | CM10: ='M08'!M9 | CN10: =IF('M08'!AG9>0,'M08'!AG9+MAX(0,CM10-'M08'!H9)*IF(AND(CJ10<>0,CK10<>0),CK10/CJ10,'M08'!V9),CM10*IF(AND(CJ10<>0,CK10<>0),CK10/CJ10,'M08'!V9)) | CO10: =IFERROR(CN10/CM10,0) | CP10: =-'M08'!S9 | CQ10: =CK10+CN10-CT10 | CR10: =IFERROR(CQ10/CP10,0) | CS10: ='M08'!T9 | CT10: ='M08'!U9 | CU10: =IFERROR(CT10/CS10,0) | CV10: ='M09'!E9 | CW10: ='M09'!F9 | CX10: =IFERROR(CW10/CV10,0) | CY10: ='M09'!M9 | CZ10: =IF('M09'!AG9>0,'M09'!AG9+MAX(0,CY10-'M09'!H9)*IF(AND(CV10<>0,CW10<>0),CW10/CV10,'M09'!V9),CY10*IF(AND(CV10<>0,CW10<>0),CW10/CV10,'M09'!V9)) | DA10: =IFERROR(CZ10/CY10,0) | DB10: =-'M09'!S9 | DC10: =CW10+CZ10-DF10 | DD10: =IFERROR(DC10/DB10,0) | DE10: ='M09'!T9 | DF10: ='M09'!U9 | DG10: =IFERROR(DF10/DE10,0) | DH10: =SUM(J10,V10,AH10,AT10,BF10,BR10,CD10,CP10,DB10) | DI10: =SUM(K10,W10,AI10,AU10,BG10,BS10,CE10,CQ10,DC10) | DJ10: =DH10/9 | DK10: =DI10/9 | DL10: =IFERROR(DI10/DH10,0) | DM10: ='M09'!V9 | DN10: =IFERROR(DL10/DM10-1,0) | DO10: ='M09'!AD9 | DP10: =DJ10-DO10 | DQ10: =COUNTIF(J10,">0")+COUNTIF(V10,">0")+COUNTIF(AH10,">0")+COUNTIF(AT10,">0")+COUNTIF(BF10,">0")+COUNTIF(BR10,">0")+COUNTIF(CD10,">0")+COUNTIF(CP10,">0")+COUNTIF(DB10,">0") | DR10: =DE10 | DS10: =IFERROR(DR10/DJ10,0) | DT10: =D10+SUM(G10,S10,AE10,AQ10,BC10,BO10,CA10,CM10,CY10)-SUM(J10,V10,AH10,AT10,BF10,BR10,CD10,CP10,DB10)-DE10
A11: ='M01'!C10 | B11: ='M01'!D10 | C11: ='M01'!A10 | D11: ='M01'!E10 | E11: ='M01'!F10 | F11: =IFERROR(E11/D11,0) | G11: ='M01'!M10 | H11: =IF('M01'!AG10>0,'M01'!AG10+MAX(0,G11-'M01'!H10)*IF(AND(D11<>0,E11<>0),E11/D11,'M01'!V10),G11*IF(AND(D11<>0,E11<>0),E11/D11,'M01'!V10)) | I11: =IFERROR(H11/G11,0) | J11: =-'M01'!S10 | K11: =E11+H11-N11 | L11: =IFERROR(K11/J11,0) | M11: ='M01'!T10 | N11: ='M01'!U10 | O11: =IFERROR(N11/M11,0) | P11: ='M02'!E10 | Q11: ='M02'!F10 | R11: =IFERROR(Q11/P11,0) | S11: ='M02'!M10 | T11: =IF('M02'!AG10>0,'M02'!AG10+MAX(0,S11-'M02'!H10)*IF(AND(P11<>0,Q11<>0),Q11/P11,'M02'!V10),S11*IF(AND(P11<>0,Q11<>0),Q11/P11,'M02'!V10)) | U11: =IFERROR(T11/S11,0) | V11: =-'M02'!S10 | W11: =Q11+T11-Z11 | X11: =IFERROR(W11/V11,0) | Y11: ='M02'!T10 | Z11: ='M02'!U10 | AA11: =IFERROR(Z11/Y11,0) | AB11: ='M03'!E10 | AC11: ='M03'!F10 | AD11: =IFERROR(AC11/AB11,0) | AE11: ='M03'!M10 | AF11: =IF('M03'!AG10>0,'M03'!AG10+MAX(0,AE11-'M03'!H10)*IF(AND(AB11<>0,AC11<>0),AC11/AB11,'M03'!V10),AE11*IF(AND(AB11<>0,AC11<>0),AC11/AB11,'M03'!V10)) | AG11: =IFERROR(AF11/AE11,0) | AH11: =-'M03'!S10 | AI11: =AC11+AF11-AL11 | AJ11: =IFERROR(AI11/AH11,0) | AK11: ='M03'!T10 | AL11: ='M03'!U10 | AM11: =IFERROR(AL11/AK11,0) | AN11: ='M04'!E10 | AO11: ='M04'!F10 | AP11: =IFERROR(AO11/AN11,0) | AQ11: ='M04'!M10 | AR11: =IF('M04'!AG10>0,'M04'!AG10+MAX(0,AQ11-'M04'!H10)*IF(AND(AN11<>0,AO11<>0),AO11/AN11,'M04'!V10),AQ11*IF(AND(AN11<>0,AO11<>0),AO11/AN11,'M04'!V10)) | AS11: =IFERROR(AR11/AQ11,0) | AT11: =-'M04'!S10 | AU11: =AO11+AR11-AX11 | AV11: =IFERROR(AU11/AT11,0) | AW11: ='M04'!T10 | AX11: ='M04'!U10 | AY11: =IFERROR(AX11/AW11,0) | AZ11: ='M05'!E10 | BA11: ='M05'!F10 | BB11: =IFERROR(BA11/AZ11,0) | BC11: ='M05'!M10 | BD11: =IF('M05'!AG10>0,'M05'!AG10+MAX(0,BC11-'M05'!H10)*IF(AND(AZ11<>0,BA11<>0),BA11/AZ11,'M05'!V10),BC11*IF(AND(AZ11<>0,BA11<>0),BA11/AZ11,'M05'!V10)) | BE11: =IFERROR(BD11/BC11,0) | BF11: =-'M05'!S10 | BG11: =BA11+BD11-BJ11 | BH11: =IFERROR(BG11/BF11,0) | BI11: ='M05'!T10 | BJ11: ='M05'!U10 | BK11: =IFERROR(BJ11/BI11,0) | BL11: ='M06'!E10 | BM11: ='M06'!F10 | BN11: =IFERROR(BM11/BL11,0) | BO11: ='M06'!M10 | BP11: =IF('M06'!AG10>0,'M06'!AG10+MAX(0,BO11-'M06'!H10)*IF(AND(BL11<>0,BM11<>0),BM11/BL11,'M06'!V10),BO11*IF(AND(BL11<>0,BM11<>0),BM11/BL11,'M06'!V10)) | BQ11: =IFERROR(BP11/BO11,0) | BR11: =-'M06'!S10 | BS11: =BM11+BP11-BV11 | BT11: =IFERROR(BS11/BR11,0) | BU11: ='M06'!T10 | BV11: ='M06'!U10 | BW11: =IFERROR(BV11/BU11,0) | BX11: ='M07'!E10 | BY11: ='M07'!F10 | BZ11: =IFERROR(BY11/BX11,0) | CA11: ='M07'!M10 | CB11: =IF('M07'!AG10>0,'M07'!AG10+MAX(0,CA11-'M07'!H10)*IF(AND(BX11<>0,BY11<>0),BY11/BX11,'M07'!V10),CA11*IF(AND(BX11<>0,BY11<>0),BY11/BX11,'M07'!V10)) | CC11: =IFERROR(CB11/CA11,0) | CD11: =-'M07'!S10 | CE11: =BY11+CB11-CH11 | CF11: =IFERROR(CE11/CD11,0) | CG11: ='M07'!T10 | CH11: ='M07'!U10 | CI11: =IFERROR(CH11/CG11,0) | CJ11: ='M08'!E10 | CK11: ='M08'!F10 | CL11: =IFERROR(CK11/CJ11,0) | CM11: ='M08'!M10 | CN11: =IF('M08'!AG10>0,'M08'!AG10+MAX(0,CM11-'M08'!H10)*IF(AND(CJ11<>0,CK11<>0),CK11/CJ11,'M08'!V10),CM11*IF(AND(CJ11<>0,CK11<>0),CK11/CJ11,'M08'!V10)) | CO11: =IFERROR(CN11/CM11,0) | CP11: =-'M08'!S10 | CQ11: =CK11+CN11-CT11 | CR11: =IFERROR(CQ11/CP11,0) | CS11: ='M08'!T10 | CT11: ='M08'!U10 | CU11: =IFERROR(CT11/CS11,0) | CV11: ='M09'!E10 | CW11: ='M09'!F10 | CX11: =IFERROR(CW11/CV11,0) | CY11: ='M09'!M10 | CZ11: =IF('M09'!AG10>0,'M09'!AG10+MAX(0,CY11-'M09'!H10)*IF(AND(CV11<>0,CW11<>0),CW11/CV11,'M09'!V10),CY11*IF(AND(CV11<>0,CW11<>0),CW11/CV11,'M09'!V10)) | DA11: =IFERROR(CZ11/CY11,0) | DB11: =-'M09'!S10 | DC11: =CW11+CZ11-DF11 | DD11: =IFERROR(DC11/DB11,0) | DE11: ='M09'!T10 | DF11: ='M09'!U10 | DG11: =IFERROR(DF11/DE11,0) | DH11: =SUM(J11,V11,AH11,AT11,BF11,BR11,CD11,CP11,DB11) | DI11: =SUM(K11,W11,AI11,AU11,BG11,BS11,CE11,CQ11,DC11) | DJ11: =DH11/9 | DK11: =DI11/9 | DL11: =IFERROR(DI11/DH11,0) | DM11: ='M09'!V10 | DN11: =IFERROR(DL11/DM11-1,0) | DO11: ='M09'!AD10 | DP11: =DJ11-DO11 | DQ11: =COUNTIF(J11,">0")+COUNTIF(V11,">0")+COUNTIF(AH11,">0")+COUNTIF(AT11,">0")+COUNTIF(BF11,">0")+COUNTIF(BR11,">0")+COUNTIF(CD11,">0")+COUNTIF(CP11,">0")+COUNTIF(DB11,">0") | DR11: =DE11 | DS11: =IFERROR(DR11/DJ11,0) | DT11: =D11+SUM(G11,S11,AE11,AQ11,BC11,BO11,CA11,CM11,CY11)-SUM(J11,V11,AH11,AT11,BF11,BR11,CD11,CP11,DB11)-DE11
A12: ='M01'!C11 | B12: ='M01'!D11 | C12: ='M01'!A11 | D12: ='M01'!E11 | E12: ='M01'!F11 | F12: =IFERROR(E12/D12,0) | G12: ='M01'!M11 | H12: =IF('M01'!AG11>0,'M01'!AG11+MAX(0,G12-'M01'!H11)*IF(AND(D12<>0,E12<>0),E12/D12,'M01'!V11),G12*IF(AND(D12<>0,E12<>0),E12/D12,'M01'!V11)) | I12: =IFERROR(H12/G12,0) | J12: =-'M01'!S11 | K12: =E12+H12-N12 | L12: =IFERROR(K12/J12,0) | M12: ='M01'!T11 | N12: ='M01'!U11 | O12: =IFERROR(N12/M12,0) | P12: ='M02'!E11 | Q12: ='M02'!F11 | R12: =IFERROR(Q12/P12,0) | S12: ='M02'!M11 | T12: =IF('M02'!AG11>0,'M02'!AG11+MAX(0,S12-'M02'!H11)*IF(AND(P12<>0,Q12<>0),Q12/P12,'M02'!V11),S12*IF(AND(P12<>0,Q12<>0),Q12/P12,'M02'!V11)) | U12: =IFERROR(T12/S12,0) | V12: =-'M02'!S11 | W12: =Q12+T12-Z12 | X12: =IFERROR(W12/V12,0) | Y12: ='M02'!T11 | Z12: ='M02'!U11 | AA12: =IFERROR(Z12/Y12,0) | AB12: ='M03'!E11 | AC12: ='M03'!F11 | AD12: =IFERROR(AC12/AB12,0) | AE12: ='M03'!M11 | AF12: =IF('M03'!AG11>0,'M03'!AG11+MAX(0,AE12-'M03'!H11)*IF(AND(AB12<>0,AC12<>0),AC12/AB12,'M03'!V11),AE12*IF(AND(AB12<>0,AC12<>0),AC12/AB12,'M03'!V11)) | AG12: =IFERROR(AF12/AE12,0) | AH12: =-'M03'!S11 | AI12: =AC12+AF12-AL12 | AJ12: =IFERROR(AI12/AH12,0) | AK12: ='M03'!T11 | AL12: ='M03'!U11 | AM12: =IFERROR(AL12/AK12,0) | AN12: ='M04'!E11 | AO12: ='M04'!F11 | AP12: =IFERROR(AO12/AN12,0) | AQ12: ='M04'!M11 | AR12: =IF('M04'!AG11>0,'M04'!AG11+MAX(0,AQ12-'M04'!H11)*IF(AND(AN12<>0,AO12<>0),AO12/AN12,'M04'!V11),AQ12*IF(AND(AN12<>0,AO12<>0),AO12/AN12,'M04'!V11)) | AS12: =IFERROR(AR12/AQ12,0) | AT12: =-'M04'!S11 | AU12: =AO12+AR12-AX12 | AV12: =IFERROR(AU12/AT12,0) | AW12: ='M04'!T11 | AX12: ='M04'!U11 | AY12: =IFERROR(AX12/AW12,0) | AZ12: ='M05'!E11 | BA12: ='M05'!F11 | BB12: =IFERROR(BA12/AZ12,0) | BC12: ='M05'!M11 | BD12: =IF('M05'!AG11>0,'M05'!AG11+MAX(0,BC12-'M05'!H11)*IF(AND(AZ12<>0,BA12<>0),BA12/AZ12,'M05'!V11),BC12*IF(AND(AZ12<>0,BA12<>0),BA12/AZ12,'M05'!V11)) | BE12: =IFERROR(BD12/BC12,0) | BF12: =-'M05'!S11 | BG12: =BA12+BD12-BJ12 | BH12: =IFERROR(BG12/BF12,0) | BI12: ='M05'!T11 | BJ12: ='M05'!U11 | BK12: =IFERROR(BJ12/BI12,0) | BL12: ='M06'!E11 | BM12: ='M06'!F11 | BN12: =IFERROR(BM12/BL12,0) | BO12: ='M06'!M11 | BP12: =IF('M06'!AG11>0,'M06'!AG11+MAX(0,BO12-'M06'!H11)*IF(AND(BL12<>0,BM12<>0),BM12/BL12,'M06'!V11),BO12*IF(AND(BL12<>0,BM12<>0),BM12/BL12,'M06'!V11)) | BQ12: =IFERROR(BP12/BO12,0) | BR12: =-'M06'!S11 | BS12: =BM12+BP12-BV12 | BT12: =IFERROR(BS12/BR12,0) | BU12: ='M06'!T11 | BV12: ='M06'!U11 | BW12: =IFERROR(BV12/BU12,0) | BX12: ='M07'!E11 | BY12: ='M07'!F11 | BZ12: =IFERROR(BY12/BX12,0) | CA12: ='M07'!M11 | CB12: =IF('M07'!AG11>0,'M07'!AG11+MAX(0,CA12-'M07'!H11)*IF(AND(BX12<>0,BY12<>0),BY12/BX12,'M07'!V11),CA12*IF(AND(BX12<>0,BY12<>0),BY12/BX12,'M07'!V11)) | CC12: =IFERROR(CB12/CA12,0) | CD12: =-'M07'!S11 | CE12: =BY12+CB12-CH12 | CF12: =IFERROR(CE12/CD12,0) | CG12: ='M07'!T11 | CH12: ='M07'!U11 | CI12: =IFERROR(CH12/CG12,0) | CJ12: ='M08'!E11 | CK12: ='M08'!F11 | CL12: =IFERROR(CK12/CJ12,0) | CM12: ='M08'!M11 | CN12: =IF('M08'!AG11>0,'M08'!AG11+MAX(0,CM12-'M08'!H11)*IF(AND(CJ12<>0,CK12<>0),CK12/CJ12,'M08'!V11),CM12*IF(AND(CJ12<>0,CK12<>0),CK12/CJ12,'M08'!V11)) | CO12: =IFERROR(CN12/CM12,0) | CP12: =-'M08'!S11 | CQ12: =CK12+CN12-CT12 | CR12: =IFERROR(CQ12/CP12,0) | CS12: ='M08'!T11 | CT12: ='M08'!U11 | CU12: =IFERROR(CT12/CS12,0) | CV12: ='M09'!E11 | CW12: ='M09'!F11 | CX12: =IFERROR(CW12/CV12,0) | CY12: ='M09'!M11 | CZ12: =IF('M09'!AG11>0,'M09'!AG11+MAX(0,CY12-'M09'!H11)*IF(AND(CV12<>0,CW12<>0),CW12/CV12,'M09'!V11),CY12*IF(AND(CV12<>0,CW12<>0),CW12/CV12,'M09'!V11)) | DA12: =IFERROR(CZ12/CY12,0) | DB12: =-'M09'!S11 | DC12: =CW12+CZ12-DF12 | DD12: =IFERROR(DC12/DB12,0) | DE12: ='M09'!T11 | DF12: ='M09'!U11 | DG12: =IFERROR(DF12/DE12,0) | DH12: =SUM(J12,V12,AH12,AT12,BF12,BR12,CD12,CP12,DB12) | DI12: =SUM(K12,W12,AI12,AU12,BG12,BS12,CE12,CQ12,DC12) | DJ12: =DH12/9 | DK12: =DI12/9 | DL12: =IFERROR(DI12/DH12,0) | DM12: ='M09'!V11 | DN12: =IFERROR(DL12/DM12-1,0) | DO12: ='M09'!AD11 | DP12: =DJ12-DO12 | DQ12: =COUNTIF(J12,">0")+COUNTIF(V12,">0")+COUNTIF(AH12,">0")+COUNTIF(AT12,">0")+COUNTIF(BF12,">0")+COUNTIF(BR12,">0")+COUNTIF(CD12,">0")+COUNTIF(CP12,">0")+COUNTIF(DB12,">0") | DR12: =DE12 | DS12: =IFERROR(DR12/DJ12,0) | DT12: =D12+SUM(G12,S12,AE12,AQ12,BC12,BO12,CA12,CM12,CY12)-SUM(J12,V12,AH12,AT12,BF12,BR12,CD12,CP12,DB12)-DE12
A13: ='M01'!C12 | B13: ='M01'!D12 | C13: ='M01'!A12 | D13: ='M01'!E12 | E13: ='M01'!F12 | F13: =IFERROR(E13/D13,0) | G13: ='M01'!M12 | H13: =IF('M01'!AG12>0,'M01'!AG12+MAX(0,G13-'M01'!H12)*IF(AND(D13<>0,E13<>0),E13/D13,'M01'!V12),G13*IF(AND(D13<>0,E13<>0),E13/D13,'M01'!V12)) | I13: =IFERROR(H13/G13,0) | J13: =-'M01'!S12 | K13: =E13+H13-N13 | L13: =IFERROR(K13/J13,0) | M13: ='M01'!T12 | N13: ='M01'!U12 | O13: =IFERROR(N13/M13,0) | P13: ='M02'!E12 | Q13: ='M02'!F12 | R13: =IFERROR(Q13/P13,0) | S13: ='M02'!M12 | T13: =IF('M02'!AG12>0,'M02'!AG12+MAX(0,S13-'M02'!H12)*IF(AND(P13<>0,Q13<>0),Q13/P13,'M02'!V12),S13*IF(AND(P13<>0,Q13<>0),Q13/P13,'M02'!V12)) | U13: =IFERROR(T13/S13,0) | V13: =-'M02'!S12 | W13: =Q13+T13-Z13 | X13: =IFERROR(W13/V13,0) | Y13: ='M02'!T12 | Z13: ='M02'!U12 | AA13: =IFERROR(Z13/Y13,0) | AB13: ='M03'!E12 | AC13: ='M03'!F12 | AD13: =IFERROR(AC13/AB13,0) | AE13: ='M03'!M12 | AF13: =IF('M03'!AG12>0,'M03'!AG12+MAX(0,AE13-'M03'!H12)*IF(AND(AB13<>0,AC13<>0),AC13/AB13,'M03'!V12),AE13*IF(AND(AB13<>0,AC13<>0),AC13/AB13,'M03'!V12)) | AG13: =IFERROR(AF13/AE13,0) | AH13: =-'M03'!S12 | AI13: =AC13+AF13-AL13 | AJ13: =IFERROR(AI13/AH13,0) | AK13: ='M03'!T12 | AL13: ='M03'!U12 | AM13: =IFERROR(AL13/AK13,0) | AN13: ='M04'!E12 | AO13: ='M04'!F12 | AP13: =IFERROR(AO13/AN13,0) | AQ13: ='M04'!M12 | AR13: =IF('M04'!AG12>0,'M04'!AG12+MAX(0,AQ13-'M04'!H12)*IF(AND(AN13<>0,AO13<>0),AO13/AN13,'M04'!V12),AQ13*IF(AND(AN13<>0,AO13<>0),AO13/AN13,'M04'!V12)) | AS13: =IFERROR(AR13/AQ13,0) | AT13: =-'M04'!S12 | AU13: =AO13+AR13-AX13 | AV13: =IFERROR(AU13/AT13,0) | AW13: ='M04'!T12 | AX13: ='M04'!U12 | AY13: =IFERROR(AX13/AW13,0) | AZ13: ='M05'!E12 | BA13: ='M05'!F12 | BB13: =IFERROR(BA13/AZ13,0) | BC13: ='M05'!M12 | BD13: =IF('M05'!AG12>0,'M05'!AG12+MAX(0,BC13-'M05'!H12)*IF(AND(AZ13<>0,BA13<>0),BA13/AZ13,'M05'!V12),BC13*IF(AND(AZ13<>0,BA13<>0),BA13/AZ13,'M05'!V12)) | BE13: =IFERROR(BD13/BC13,0) | BF13: =-'M05'!S12 | BG13: =BA13+BD13-BJ13 | BH13: =IFERROR(BG13/BF13,0) | BI13: ='M05'!T12 | BJ13: ='M05'!U12 | BK13: =IFERROR(BJ13/BI13,0) | BL13: ='M06'!E12 | BM13: ='M06'!F12 | BN13: =IFERROR(BM13/BL13,0) | BO13: ='M06'!M12 | BP13: =IF('M06'!AG12>0,'M06'!AG12+MAX(0,BO13-'M06'!H12)*IF(AND(BL13<>0,BM13<>0),BM13/BL13,'M06'!V12),BO13*IF(AND(BL13<>0,BM13<>0),BM13/BL13,'M06'!V12)) | BQ13: =IFERROR(BP13/BO13,0) | BR13: =-'M06'!S12 | BS13: =BM13+BP13-BV13 | BT13: =IFERROR(BS13/BR13,0) | BU13: ='M06'!T12 | BV13: ='M06'!U12 | BW13: =IFERROR(BV13/BU13,0) | BX13: ='M07'!E12 | BY13: ='M07'!F12 | BZ13: =IFERROR(BY13/BX13,0) | CA13: ='M07'!M12 | CB13: =IF('M07'!AG12>0,'M07'!AG12+MAX(0,CA13-'M07'!H12)*IF(AND(BX13<>0,BY13<>0),BY13/BX13,'M07'!V12),CA13*IF(AND(BX13<>0,BY13<>0),BY13/BX13,'M07'!V12)) | CC13: =IFERROR(CB13/CA13,0) | CD13: =-'M07'!S12 | CE13: =BY13+CB13-CH13 | CF13: =IFERROR(CE13/CD13,0) | CG13: ='M07'!T12 | CH13: ='M07'!U12 | CI13: =IFERROR(CH13/CG13,0) | CJ13: ='M08'!E12 | CK13: ='M08'!F12 | CL13: =IFERROR(CK13/CJ13,0) | CM13: ='M08'!M12 | CN13: =IF('M08'!AG12>0,'M08'!AG12+MAX(0,CM13-'M08'!H12)*IF(AND(CJ13<>0,CK13<>0),CK13/CJ13,'M08'!V12),CM13*IF(AND(CJ13<>0,CK13<>0),CK13/CJ13,'M08'!V12)) | CO13: =IFERROR(CN13/CM13,0) | CP13: =-'M08'!S12 | CQ13: =CK13+CN13-CT13 | CR13: =IFERROR(CQ13/CP13,0) | CS13: ='M08'!T12 | CT13: ='M08'!U12 | CU13: =IFERROR(CT13/CS13,0) | CV13: ='M09'!E12 | CW13: ='M09'!F12 | CX13: =IFERROR(CW13/CV13,0) | CY13: ='M09'!M12 | CZ13: =IF('M09'!AG12>0,'M09'!AG12+MAX(0,CY13-'M09'!H12)*IF(AND(CV13<>0,CW13<>0),CW13/CV13,'M09'!V12),CY13*IF(AND(CV13<>0,CW13<>0),CW13/CV13,'M09'!V12)) | DA13: =IFERROR(CZ13/CY13,0) | DB13: =-'M09'!S12 | DC13: =CW13+CZ13-DF13 | DD13: =IFERROR(DC13/DB13,0) | DE13: ='M09'!T12 | DF13: ='M09'!U12 | DG13: =IFERROR(DF13/DE13,0) | DH13: =SUM(J13,V13,AH13,AT13,BF13,BR13,CD13,CP13,DB13) | DI13: =SUM(K13,W13,AI13,AU13,BG13,BS13,CE13,CQ13,DC13) | DJ13: =DH13/9 | DK13: =DI13/9 | DL13: =IFERROR(DI13/DH13,0) | DM13: ='M09'!V12 | DN13: =IFERROR(DL13/DM13-1,0) | DO13: ='M09'!AD12 | DP13: =DJ13-DO13 | DQ13: =COUNTIF(J13,">0")+COUNTIF(V13,">0")+COUNTIF(AH13,">0")+COUNTIF(AT13,">0")+COUNTIF(BF13,">0")+COUNTIF(BR13,">0")+COUNTIF(CD13,">0")+COUNTIF(CP13,">0")+COUNTIF(DB13,">0") | DR13: =DE13 | DS13: =IFERROR(DR13/DJ13,0) | DT13: =D13+SUM(G13,S13,AE13,AQ13,BC13,BO13,CA13,CM13,CY13)-SUM(J13,V13,AH13,AT13,BF13,BR13,CD13,CP13,DB13)-DE13
A14: ='M01'!C13 | B14: ='M01'!D13 | C14: ='M01'!A13 | D14: ='M01'!E13 | E14: ='M01'!F13 | F14: =IFERROR(E14/D14,0) | G14: ='M01'!M13 | H14: =IF('M01'!AG13>0,'M01'!AG13+MAX(0,G14-'M01'!H13)*IF(AND(D14<>0,E14<>0),E14/D14,'M01'!V13),G14*IF(AND(D14<>0,E14<>0),E14/D14,'M01'!V13)) | I14: =IFERROR(H14/G14,0) | J14: =-'M01'!S13 | K14: =E14+H14-N14 | L14: =IFERROR(K14/J14,0) | M14: ='M01'!T13 | N14: ='M01'!U13 | O14: =IFERROR(N14/M14,0) | P14: ='M02'!E13 | Q14: ='M02'!F13 | R14: =IFERROR(Q14/P14,0) | S14: ='M02'!M13 | T14: =IF('M02'!AG13>0,'M02'!AG13+MAX(0,S14-'M02'!H13)*IF(AND(P14<>0,Q14<>0),Q14/P14,'M02'!V13),S14*IF(AND(P14<>0,Q14<>0),Q14/P14,'M02'!V13)) | U14: =IFERROR(T14/S14,0) | V14: =-'M02'!S13 | W14: =Q14+T14-Z14 | X14: =IFERROR(W14/V14,0) | Y14: ='M02'!T13 | Z14: ='M02'!U13 | AA14: =IFERROR(Z14/Y14,0) | AB14: ='M03'!E13 | AC14: ='M03'!F13 | AD14: =IFERROR(AC14/AB14,0) | AE14: ='M03'!M13 | AF14: =IF('M03'!AG13>0,'M03'!AG13+MAX(0,AE14-'M03'!H13)*IF(AND(AB14<>0,AC14<>0),AC14/AB14,'M03'!V13),AE14*IF(AND(AB14<>0,AC14<>0),AC14/AB14,'M03'!V13)) | AG14: =IFERROR(AF14/AE14,0) | AH14: =-'M03'!S13 | AI14: =AC14+AF14-AL14 | AJ14: =IFERROR(AI14/AH14,0) | AK14: ='M03'!T13 | AL14: ='M03'!U13 | AM14: =IFERROR(AL14/AK14,0) | AN14: ='M04'!E13 | AO14: ='M04'!F13 | AP14: =IFERROR(AO14/AN14,0) | AQ14: ='M04'!M13 | AR14: =IF('M04'!AG13>0,'M04'!AG13+MAX(0,AQ14-'M04'!H13)*IF(AND(AN14<>0,AO14<>0),AO14/AN14,'M04'!V13),AQ14*IF(AND(AN14<>0,AO14<>0),AO14/AN14,'M04'!V13)) | AS14: =IFERROR(AR14/AQ14,0) | AT14: =-'M04'!S13 | AU14: =AO14+AR14-AX14 | AV14: =IFERROR(AU14/AT14,0) | AW14: ='M04'!T13 | AX14: ='M04'!U13 | AY14: =IFERROR(AX14/AW14,0) | AZ14: ='M05'!E13 | BA14: ='M05'!F13 | BB14: =IFERROR(BA14/AZ14,0) | BC14: ='M05'!M13 | BD14: =IF('M05'!AG13>0,'M05'!AG13+MAX(0,BC14-'M05'!H13)*IF(AND(AZ14<>0,BA14<>0),BA14/AZ14,'M05'!V13),BC14*IF(AND(AZ14<>0,BA14<>0),BA14/AZ14,'M05'!V13)) | BE14: =IFERROR(BD14/BC14,0) | BF14: =-'M05'!S13 | BG14: =BA14+BD14-BJ14 | BH14: =IFERROR(BG14/BF14,0) | BI14: ='M05'!T13 | BJ14: ='M05'!U13 | BK14: =IFERROR(BJ14/BI14,0) | BL14: ='M06'!E13 | BM14: ='M06'!F13 | BN14: =IFERROR(BM14/BL14,0) | BO14: ='M06'!M13 | BP14: =IF('M06'!AG13>0,'M06'!AG13+MAX(0,BO14-'M06'!H13)*IF(AND(BL14<>0,BM14<>0),BM14/BL14,'M06'!V13),BO14*IF(AND(BL14<>0,BM14<>0),BM14/BL14,'M06'!V13)) | BQ14: =IFERROR(BP14/BO14,0) | BR14: =-'M06'!S13 | BS14: =BM14+BP14-BV14 | BT14: =IFERROR(BS14/BR14,0) | BU14: ='M06'!T13 | BV14: ='M06'!U13 | BW14: =IFERROR(BV14/BU14,0) | BX14: ='M07'!E13 | BY14: ='M07'!F13 | BZ14: =IFERROR(BY14/BX14,0) | CA14: ='M07'!M13 | CB14: =IF('M07'!AG13>0,'M07'!AG13+MAX(0,CA14-'M07'!H13)*IF(AND(BX14<>0,BY14<>0),BY14/BX14,'M07'!V13),CA14*IF(AND(BX14<>0,BY14<>0),BY14/BX14,'M07'!V13)) | CC14: =IFERROR(CB14/CA14,0) | CD14: =-'M07'!S13 | CE14: =BY14+CB14-CH14 | CF14: =IFERROR(CE14/CD14,0) | CG14: ='M07'!T13 | CH14: ='M07'!U13 | CI14: =IFERROR(CH14/CG14,0) | CJ14: ='M08'!E13 | CK14: ='M08'!F13 | CL14: =IFERROR(CK14/CJ14,0) | CM14: ='M08'!M13 | CN14: =IF('M08'!AG13>0,'M08'!AG13+MAX(0,CM14-'M08'!H13)*IF(AND(CJ14<>0,CK14<>0),CK14/CJ14,'M08'!V13),CM14*IF(AND(CJ14<>0,CK14<>0),CK14/CJ14,'M08'!V13)) | CO14: =IFERROR(CN14/CM14,0) | CP14: =-'M08'!S13 | CQ14: =CK14+CN14-CT14 | CR14: =IFERROR(CQ14/CP14,0) | CS14: ='M08'!T13 | CT14: ='M08'!U13 | CU14: =IFERROR(CT14/CS14,0) | CV14: ='M09'!E13 | CW14: ='M09'!F13 | CX14: =IFERROR(CW14/CV14,0) | CY14: ='M09'!M13 | CZ14: =IF('M09'!AG13>0,'M09'!AG13+MAX(0,CY14-'M09'!H13)*IF(AND(CV14<>0,CW14<>0),CW14/CV14,'M09'!V13),CY14*IF(AND(CV14<>0,CW14<>0),CW14/CV14,'M09'!V13)) | DA14: =IFERROR(CZ14/CY14,0) | DB14: =-'M09'!S13 | DC14: =CW14+CZ14-DF14 | DD14: =IFERROR(DC14/DB14,0) | DE14: ='M09'!T13 | DF14: ='M09'!U13 | DG14: =IFERROR(DF14/DE14,0) | DH14: =SUM(J14,V14,AH14,AT14,BF14,BR14,CD14,CP14,DB14) | DI14: =SUM(K14,W14,AI14,AU14,BG14,BS14,CE14,CQ14,DC14) | DJ14: =DH14/9 | DK14: =DI14/9 | DL14: =IFERROR(DI14/DH14,0) | DM14: ='M09'!V13 | DN14: =IFERROR(DL14/DM14-1,0) | DO14: ='M09'!AD13 | DP14: =DJ14-DO14 | DQ14: =COUNTIF(J14,">0")+COUNTIF(V14,">0")+COUNTIF(AH14,">0")+COUNTIF(AT14,">0")+COUNTIF(BF14,">0")+COUNTIF(BR14,">0")+COUNTIF(CD14,">0")+COUNTIF(CP14,">0")+COUNTIF(DB14,">0") | DR14: =DE14 | DS14: =IFERROR(DR14/DJ14,0) | DT14: =D14+SUM(G14,S14,AE14,AQ14,BC14,BO14,CA14,CM14,CY14)-SUM(J14,V14,AH14,AT14,BF14,BR14,CD14,CP14,DB14)-DE14
... A564: ='M01'!C563 | B564: ='M01'!D563 | C564: ='M01'!A563 | D564: ='M01'!E563 | E564: ='M01'!F563 | F564: =IFERROR(E564/D564,0) | G564: ='M01'!M563 | H564: =IF('M01'!AG563>0,'M01'!AG563+MAX(0,G564-'M01'!H563)*IF(AND(D564<>0,E564<>0),E564/D564,'M01'!V563),G564*IF(AND(D564<>0,E564<>0),E564/D564,'M01'!V563)) | I564: =IFERROR(H564/G564,0) | J564: =-'M01'!S563 | K564: =E564+H564-N564 | L564: =IFERROR(K564/J564,0) | M564: ='M01'!T563 | N564: ='M01'!U563 | O564: =IFERROR(N564/M564,0) | P564: ='M02'!E563 | Q564: ='M02'!F563 | R564: =IFERROR(Q564/P564,0) | S564: ='M02'!M563 | T564: =IF('M02'!AG563>0,'M02'!AG563+MAX(0,S564-'M02'!H563)*IF(AND(P564<>0,Q564<>0),Q564/P564,'M02'!V563),S564*IF(AND(P564<>0,Q564<>0),Q564/P564,'M02'!V563)) | U564: =IFERROR(T564/S564,0) | V564: =-'M02'!S563 | W564: =Q564+T564-Z564 | X564: =IFERROR(W564/V564,0) | Y564: ='M02'!T563 | Z564: ='M02'!U563 | AA564: =IFERROR(Z564/Y564,0) | AB564: ='M03'!E563 | AC564: ='M03'!F563 | AD564: =IFERROR(AC564/AB564,0) | AE564: ='M03'!M563 | AF564: =IF('M03'!AG563>0,'M03'!AG563+MAX(0,AE564-'M03'!H563)*IF(AND(AB564<>0,AC564<>0),AC564/AB564,'M03'!V563),AE564*IF(AND(AB564<>0,AC564<>0),AC564/AB564,'M03'!V563)) | AG564: =IFERROR(AF564/AE564,0) | AH564: =-'M03'!S563 | AI564: =AC564+AF564-AL564 | AJ564: =IFERROR(AI564/AH564,0) | AK564: ='M03'!T563 | AL564: ='M03'!U563 | AM564: =IFERROR(AL564/AK564,0) | AN564: ='M04'!E563 | AO564: ='M04'!F563 | AP564: =IFERROR(AO564/AN564,0) | AQ564: ='M04'!M563 | AR564: =IF('M04'!AG563>0,'M04'!AG563+MAX(0,AQ564-'M04'!H563)*IF(AND(AN564<>0,AO564<>0),AO564/AN564,'M04'!V563),AQ564*IF(AND(AN564<>0,AO564<>0),AO564/AN564,'M04'!V563)) | AS564: =IFERROR(AR564/AQ564,0) | AT564: =-'M04'!S563 | AU564: =AO564+AR564-AX564 | AV564: =IFERROR(AU564/AT564,0) | AW564: ='M04'!T563 | AX564: ='M04'!U563 | AY564: =IFERROR(AX564/AW564,0) | AZ564: ='M05'!E563 | BA564: ='M05'!F563 | BB564: =IFERROR(BA564/AZ564,0) | BC564: ='M05'!M563 | BD564: =IF('M05'!AG563>0,'M05'!AG563+MAX(0,BC564-'M05'!H563)*IF(AND(AZ564<>0,BA564<>0),BA564/AZ564,'M05'!V563),BC564*IF(AND(AZ564<>0,BA564<>0),BA564/AZ564,'M05'!V563)) | BE564: =IFERROR(BD564/BC564,0) | BF564: =-'M05'!S563 | BG564: =BA564+BD564-BJ564 | BH564: =IFERROR(BG564/BF564,0) | BI564: ='M05'!T563 | BJ564: ='M05'!U563 | BK564: =IFERROR(BJ564/BI564,0) | BL564: ='M06'!E563 | BM564: ='M06'!F563 | BN564: =IFERROR(BM564/BL564,0) | BO564: ='M06'!M563 | BP564: =IF('M06'!AG563>0,'M06'!AG563+MAX(0,BO564-'M06'!H563)*IF(AND(BL564<>0,BM564<>0),BM564/BL564,'M06'!V563),BO564*IF(AND(BL564<>0,BM564<>0),BM564/BL564,'M06'!V563)) | BQ564: =IFERROR(BP564/BO564,0) | BR564: =-'M06'!S563 | BS564: =BM564+BP564-BV564 | BT564: =IFERROR(BS564/BR564,0) | BU564: ='M06'!T563 | BV564: ='M06'!U563 | BW564: =IFERROR(BV564/BU564,0) | BX564: ='M07'!E563 | BY564: ='M07'!F563 | BZ564: =IFERROR(BY564/BX564,0) | CA564: ='M07'!M563 | CB564: =IF('M07'!AG563>0,'M07'!AG563+MAX(0,CA564-'M07'!H563)*IF(AND(BX564<>0,BY564<>0),BY564/BX564,'M07'!V563),CA564*IF(AND(BX564<>0,BY564<>0),BY564/BX564,'M07'!V563)) | CC564: =IFERROR(CB564/CA564,0) | CD564: =-'M07'!S563 | CE564: =BY564+CB564-CH564 | CF564: =IFERROR(CE564/CD564,0) | CG564: ='M07'!T563 | CH564: ='M07'!U563 | CI564: =IFERROR(CH564/CG564,0) | CJ564: ='M08'!E563 | CK564: ='M08'!F563 | CL564: =IFERROR(CK564/CJ564,0) | CM564: ='M08'!M563 | CN564: =IF('M08'!AG563>0,'M08'!AG563+MAX(0,CM564-'M08'!H563)*IF(AND(CJ564<>0,CK564<>0),CK564/CJ564,'M08'!V563),CM564*IF(AND(CJ564<>0,CK564<>0),CK564/CJ564,'M08'!V563)) | CO564: =IFERROR(CN564/CM564,0) | CP564: =-'M08'!S563 | CQ564: =CK564+CN564-CT564 | CR564: =IFERROR(CQ564/CP564,0) | CS564: ='M08'!T563 | CT564: ='M08'!U563 | CU564: =IFERROR(CT564/CS564,0) | CV564: ='M09'!E563 | CW564: ='M09'!F563 | CX564: =IFERROR(CW564/CV564,0) | CY564: ='M09'!M563 | CZ564: =IF('M09'!AG563>0,'M09'!AG563+MAX(0,CY564-'M09'!H563)*IF(AND(CV564<>0,CW564<>0),CW564/CV564,'M09'!V563),CY564*IF(AND(CV564<>0,CW564<>0),CW564/CV564,'M09'!V563)) | DA564: =IFERROR(CZ564/CY564,0) | DB564: =-'M09'!S563 | DC564: =CW564+CZ564-DF564 | DD564: =IFERROR(DC564/DB564,0) | DE564: ='M09'!T563 | DF564: ='M09'!U563 | DG564: =IFERROR(DF564/DE564,0) | DH564: =SUM(J564,V564,AH564,AT564,BF564,BR564,CD564,CP564,DB564) | DI564: =SUM(K564,W564,AI564,AU564,BG564,BS564,CE564,CQ564,DC564) | DJ564: =DH564/9 | DK564: =DI564/9 | DL564: =IFERROR(DI564/DH564,0) | DM564: ='M09'!V563 | DN564: =IFERROR(DL564/DM564-1,0) | DO564: ='M09'!AD563 | DP564: =DJ564-DO564 | DQ564: =COUNTIF(J564,">0")+COUNTIF(V564,">0")+COUNTIF(AH564,">0")+COUNTIF(AT564,">0")+COUNTIF(BF564,">0")+COUNTIF(BR564,">0")+COUNTIF(CD564,">0")+COUNTIF(CP564,">0")+COUNTIF(DB564,">0") | DR564: =DE564 | DS564: =IFERROR(DR564/DJ564,0) | DT564: =D564+SUM(G564,S564,AE564,AQ564,BC564,BO564,CA564,CM564,CY564)-SUM(J564,V564,AH564,AT564,BF564,BR564,CD564,CP564,DB564)-DE564

Sheet Summary
A1: الفئة الفرعية SubCateg | B1: عدد المواد Items | C1: عدد المواد التي لها إخراج Items with Out Movement | D1: إجمالي كمية الإخراج 9 أشهر Total Out Qty 9M | E1: إجمالي كلفة الإخراج 9 أشهر Total Out Cost 9M | F1: متوسط كلفة الاستهلاك الشهري Avg Monthly Out Cost | G1: حصة من إجمالي كلفة الإخراج % Share of Total Out Cost % | H1: مجموع التدقيق (يجب أن يكون 0) Sum of Check
A2: ADTV | B2: =COUNTIF(Model!$C$3:$C$564,A2) | C2: =COUNTIFS(Model!$C$3:$C$564,A2,Model!$DQ$3:$DQ$564,">0") | D2: =SUMIF(Model!$C$3:$C$564,A2,Model!$DH$3:$DH$564) | E2: =SUMIF(Model!$C$3:$C$564,A2,Model!$DI$3:$DI$564) | F2: =SUMIF(Model!$C$3:$C$564,A2,Model!$DK$3:$DK$564) | G2: =IFERROR(E2/$E$24,0) | H2: =SUMIF(Model!$C$3:$C$564,A2,Model!$DT$3:$DT$564)
A3: ASWT | B3: =COUNTIF(Model!$C$3:$C$564,A3) | C3: =COUNTIFS(Model!$C$3:$C$564,A3,Model!$DQ$3:$DQ$564,">0") | D3: =SUMIF(Model!$C$3:$C$564,A3,Model!$DH$3:$DH$564) | E3: =SUMIF(Model!$C$3:$C$564,A3,Model!$DI$3:$DI$564) | F3: =SUMIF(Model!$C$3:$C$564,A3,Model!$DK$3:$DK$564) | G3: =IFERROR(E3/$E$24,0) | H3: =SUMIF(Model!$C$3:$C$564,A3,Model!$DT$3:$DT$564)
A4: BIS | B4: =COUNTIF(Model!$C$3:$C$564,A4) | C4: =COUNTIFS(Model!$C$3:$C$564,A4,Model!$DQ$3:$DQ$564,">0") | D4: =SUMIF(Model!$C$3:$C$564,A4,Model!$DH$3:$DH$564) | E4: =SUMIF(Model!$C$3:$C$564,A4,Model!$DI$3:$DI$564) | F4: =SUMIF(Model!$C$3:$C$564,A4,Model!$DK$3:$DK$564) | G4: =IFERROR(E4/$E$24,0) | H4: =SUMIF(Model!$C$3:$C$564,A4,Model!$DT$3:$DT$564)
A5: BTQ | B5: =COUNTIF(Model!$C$3:$C$564,A5) | C5: =COUNTIFS(Model!$C$3:$C$564,A5,Model!$DQ$3:$DQ$564,">0") | D5: =SUMIF(Model!$C$3:$C$564,A5,Model!$DH$3:$DH$564) | E5: =SUMIF(Model!$C$3:$C$564,A5,Model!$DI$3:$DI$564) | F5: =SUMIF(Model!$C$3:$C$564,A5,Model!$DK$3:$DK$564) | G5: =IFERROR(E5/$E$24,0) | H5: =SUMIF(Model!$C$3:$C$564,A5,Model!$DT$3:$DT$564)
