Workbook

Sheet الفواتير
A1: OrderNo | B1: =مجاميع!A2 -> 2600325 | G1: OrderDate | H1: =مجاميع!B2 -> 46084
A2: Name | B2: =مجاميع!C2 -> BakeMark USA LLC
A4: ItemNo | B4: ItemDesc_Ara | C4: Qty | D4: U.Price | E4: U.Cost | F4: O.H | G4: Total Cost | H4: Total Value | I4: Margin | J4: Margin %
A5: =مجاميع!A5 -> FGM.FIL.3535.0343 | B5: =مجاميع!B5 -> Kunafa Pistachio Crunchy Filling ( BAKE MARK - SING ) 6 Pail *1 kg | C5: =مجاميع!C5 -> 5070 | D5: =مجاميع!D5 -> 5.921 | E5: =مجاميع!I5 -> 2.3253 | F5: 0.18 | G5: =+(C5*E5)*(F5)+(C5*E5) -> 13911.34 | H5: =مجاميع!E5 -> 30021.498 | I5: =+H5-G5 -> 16110.158 | J5: =(H5-G5)/H5 -> 0.53662073
D6: =+D5/0.71 -> 8.3394366 | E6: =+E5/0.71 -> 3.2750704 | G6: =+G5/0.71 -> 19593.436 | H6: =+H5/0.71 -> 42283.8 | I6: =+I5/0.71 -> 22690.364
A7: =مجاميع!A6 -> FGM.FIL.3536.0343 | B7: =مجاميع!B6 -> Kunafa Pistachio Filling ( BAKE MARK - SING ) 4 Pail *5 kg | C7: =مجاميع!C6 -> 400 | D7: =مجاميع!D6 -> 5.921 | E7: =مجاميع!I6 -> 2.2266 | F7: 0.18 | G7: =+(C7*E7)*(F7)+(C7*E7) -> 1050.9552 | H7: =مجاميع!E6 -> 2368.56 | I7: =+H7-G7 -> 1317.6048 | J7: =(H7-G7)/H7 -> 0.55628939
D8: =+D7/0.71 -> 8.3394366 | E8: =+E7/0.71 -> 3.1360563 | G8: =+G7/0.71 -> 1480.2186 | H8: =+H7/0.71 -> 3336 | I8: =+I7/0.71 -> 1855.7814
A9: =مجاميع!A7 -> FGM.FIL.3537.0343 | B9: =مجاميع!B7 -> Bisco Crunchy Filling ( BAKE MARK - SING ) 6 Pail *1 kg | C9: =مجاميع!C7 -> 1014 | D9: =مجاميع!D7 -> 3.656 | E9: =مجاميع!I7 -> 1.6663 | F9: 0.18 | G9: =+(C9*E9)*(F9)+(C9*E9) -> 1993.7613 | H9: =مجاميع!E7 -> 3707.691 | I9: =+H9-G9 -> 1713.9297 | J9: =(H9-G9)/H9 -> 0.46226337
D10: =+D9/0.71 -> 5.1492958 | E10: =+E9/0.71 -> 2.3469014 | G10: =+G9/0.71 -> 2808.1145 | H10: =+H9/0.71 -> 5222.1 | I10: =+I9/0.71 -> 2413.9855
A11: =مجاميع!A8 -> FGM.FIL.3871.0343 | B11: =مجاميع!B8 -> Kunafa Peanut Butter Filling ( Bake Mark - SING ) 6Pail *1 kg | C11: =مجاميع!C8 -> 300 | D11: =مجاميع!D8 -> 2.982 | E11: =مجاميع!I8 -> 2.2401 | F11: 0.18 | G11: =+(C11*E11)*(F11)+(C11*E11) -> 792.9954 | H11: =مجاميع!E8 -> 894.6 | I11: =+H11-G11 -> 101.6046 | J11: =(H11-G11)/H11 -> 0.11357545
D12: =+D11/0.71 -> 4.2 | E12: =+E11/0.71 -> 3.1550704 | G12: =+G11/0.71 -> 1116.8949 | H12: =+H11/0.71 -> 1260 | I12: =+I11/0.71 -> 143.10507
A13: =مجاميع!A9 -> FGM.FIL.3873.0343 | B13: =مجاميع!B9 -> Milk Chocolate Cream With Fuellitine Crunchy (Bake Mark - SING ) 6 Pail * 1 KG | C13: =مجاميع!C9 -> 102 | D13: =مجاميع!D9 -> 4.047 | E13: =مجاميع!I9 -> 2.0704 | F13: 0.18 | G13: =+(C13*E13)*(F13)+(C13*E13) -> 249.19334 | H13: =مجاميع!E9 -> 412.794 | I13: =+H13-G13 -> 163.60066 | J13: =(H13-G13)/H13 -> 0.39632518
D14: =+D13/0.71 -> 5.7 | E14: =+E13/0.71 -> 2.9160563 | G14: =+G13/0.71 -> 350.97654 | H14: =+H13/0.71 -> 581.4 | I14: =+I13/0.71 -> 230.42346
A15: =مجاميع!A10 -> FGM.FIL.3874.0343 | B15: =مجاميع!B10 -> Milk Chocolate Cream With Fuellitine ( Bake Mark - SING ) 4 Pail *5 kg | C15: =مجاميع!C10 -> 2000 | D15: =مجاميع!D10 -> 4.047 | E15: =مجاميع!I10 -> 1.9716 | F15: 0.18 | G15: =+(C15*E15)*(F15)+(C15*E15) -> 4652.976 | H15: =مجاميع!E10 -> 8094 | I15: =+H15-G15 -> 3441.024 | J15: =(H15-G15)/H15 -> 0.42513269
D16: =+D15/0.71 -> 5.7 | E16: =+E15/0.71 -> 2.7769014 | G16: =+G15/0.71 -> 6553.4873 | H16: =+H15/0.71 -> 11400 | I16: =+I15/0.71 -> 4846.5127
A17: =مجاميع!A11 -> 0 | B17: =مجاميع!B11 -> 0 | C17: =مجاميع!C11 -> 0 | D17: =مجاميع!D11 -> 0 | E17: =مجاميع!I11 -> 0 | F17: 0.18 | G17: =+(C17*E17)*(F17)+(C17*E17) -> 0 | H17: =مجاميع!E11 -> 0 | I17: =+H17-G17 -> 0 | J17: =(H17-G17)/H17 -> #DIV/0!
D18: =+D17/0.71 -> 0 | E18: =+E17/0.71 -> 0 | G18: =+G17/0.71 -> 0 | H18: =+H17/0.71 -> 0 | I18: =+I17/0.71 -> 0
A19: =مجاميع!A12 -> 0 | B19: =مجاميع!B12 -> 0 | C19: =مجاميع!C12 -> 0 | D19: =مجاميع!D12 -> 0 | E19: =مجاميع!I12 -> 0 | F19: 0.18 | G19: =+(C19*E19)*(F19)+(C19*E19) -> 0 | H19: =مجاميع!E12 -> 0 | I19: =+H19-G19 -> 0 | J19: =(H19-G19)/H19 -> #DIV/0!
D20: =+D19/0.71 -> 0 | E20: =+E19/0.71 -> 0 | G20: =+G19/0.71 -> 0 | H20: =+H19/0.71 -> 0 | I20: =+I19/0.71 -> 0
A21: =مجاميع!A13 -> 0 | B21: =مجاميع!B13 -> 0 | C21: =مجاميع!C13 -> 0 | D21: =مجاميع!D13 -> 0 | E21: =مجاميع!I13 -> 0 | F21: 0.18 | G21: =+(C21*E21)*(F21)+(C21*E21) -> 0 | H21: =مجاميع!E13 -> 0 | I21: =+H21-G21 -> 0 | J21: =(H21-G21)/H21 -> #DIV/0!
D22: =+D21/0.71 -> 0 | E22: =+E21/0.71 -> 0 | G22: =+G21/0.71 -> 0 | H22: =+H21/0.71 -> 0 | I22: =+I21/0.71 -> 0
A23: =مجاميع!A14 -> 0 | B23: =مجاميع!B14 -> 0 | C23: =مجاميع!C14 -> 0 | D23: =مجاميع!D14 -> 0 | E23: =مجاميع!I14 -> 0 | F23: 0.18 | G23: =+(C23*E23)*(F23)+(C23*E23) -> 0 | H23: =مجاميع!E14 -> 0 | I23: =+H23-G23 -> 0 | J23: =(H23-G23)/H23 -> #DIV/0!
D24: =+D23/0.71 -> 0 | E24: =+E23/0.71 -> 0 | G24: =+G23/0.71 -> 0 | H24: =+H23/0.71 -> 0 | I24: =+I23/0.71 -> 0
A25: =مجاميع!A15 -> 0 | B25: =مجاميع!B15 -> 0 | C25: =مجاميع!C15 -> 0 | D25: =مجاميع!D15 -> 0 | E25: =مجاميع!I15 -> 0 | F25: 0.18 | G25: =+(C25*E25)*(F25)+(C25*E25) -> 0 | H25: =مجاميع!E15 -> 0 | I25: =+H25-G25 -> 0 | J25: =(H25-G25)/H25 -> #DIV/0!
D26: =+D25/0.71 -> 0 | E26: =+E25/0.71 -> 0 | G26: =+G25/0.71 -> 0 | H26: =+H25/0.71 -> 0 | I26: =+I25/0.71 -> 0
A27: =مجاميع!A16 -> 0 | B27: =مجاميع!B16 -> 0 | C27: =مجاميع!C16 -> 0 | D27: =مجاميع!D16 -> 0 | E27: =مجاميع!I16 -> 0 | F27: 0.18 | G27: =+(C27*E27)*(F27)+(C27*E27) -> 0 | H27: =مجاميع!E16 -> 0 | I27: =+H27-G27 -> 0 | J27: =(H27-G27)/H27 -> #DIV/0!
D28: =+D27/0.71 -> 0 | E28: =+E27/0.71 -> 0 | G28: =+G27/0.71 -> 0 | H28: =+H27/0.71 -> 0 | I28: =+I27/0.71 -> 0
A29: =مجاميع!A17 -> 0 | B29: =مجاميع!B17 -> 0 | C29: =مجاميع!C17 -> 0 | D29: =مجاميع!D17 -> 0 | E29: =مجاميع!I17 -> 0 | F29: 0.18 | G29: =+(C29*E29)*(F29)+(C29*E29) -> 0 | H29: =مجاميع!E17 -> 0 | I29: =+H29-G29 -> 0 | J29: =(H29-G29)/H29 -> #DIV/0!
D30: =+D29/0.71 -> 0 | E30: =+E29/0.71 -> 0 | G30: =+G29/0.71 -> 0 | H30: =+H29/0.71 -> 0 | I30: =+I29/0.71 -> 0
A31: =مجاميع!A18 -> 0 | B31: =مجاميع!B18 -> 0 | C31: =مجاميع!C18 -> 0 | D31: =مجاميع!D18 -> 0 | E31: =مجاميع!I18 -> 0 | F31: 0.18 | G31: =+(C31*E31)*(F31)+(C31*E31) -> 0 | H31: =مجاميع!E18 -> 0 | I31: =+H31-G31 -> 0 | J31: =(H31-G31)/H31 -> #DIV/0!
D32: =+D31/0.71 -> 0 | E32: =+E31/0.71 -> 0 | G32: =+G31/0.71 -> 0 | H32: =+H31/0.71 -> 0 | I32: =+I31/0.71 -> 0
A33: =مجاميع!A19 -> 0 | B33: =مجاميع!B19 -> 0 | C33: =مجاميع!C19 -> 0 | D33: =مجاميع!D19 -> 0 | E33: =مجاميع!I19 -> 0 | F33: 0.18 | G33: =+(C33*E33)*(F33)+(C33*E33) -> 0 | H33: =مجاميع!E19 -> 0 | I33: =+H33-G33 -> 0 | J33: =(H33-G33)/H33 -> #DIV/0!
D34: =+D33/0.71 -> 0 | E34: =+E33/0.71 -> 0 | G34: =+G33/0.71 -> 0 | H34: =+H33/0.71 -> 0 | I34: =+I33/0.71 -> 0
A35: =مجاميع!A20 -> 0 | B35: =مجاميع!B20 -> 0 | C35: =مجاميع!C20 -> 0 | D35: =مجاميع!D20 -> 0 | E35: =مجاميع!I20 -> 0 | F35: 0.18 | G35: =+(C35*E35)*(F35)+(C35*E35) -> 0 | H35: =مجاميع!E20 -> 0 | I35: =+H35-G35 -> 0 | J35: =(H35-G35)/H35 -> #DIV/0!
D36: =+D35/0.71 -> 0 | E36: =+E35/0.71 -> 0 | G36: =+G35/0.71 -> 0 | H36: =+H35/0.71 -> 0 | I36: =+I35/0.71 -> 0
A37: =مجاميع!A21 -> 0 | B37: =مجاميع!B21 -> 0 | C37: =مجاميع!C21 -> 0 | D37: =مجاميع!D21 -> 0 | E37: =مجاميع!I21 -> 0 | F37: 0.18 | G37: =+(C37*E37)*(F37)+(C37*E37) -> 0 | H37: =مجاميع!E21 -> 0 | I37: =+H37-G37 -> 0 | J37: =(H37-G37)/H37 -> #DIV/0!
D38: =+D37/0.71 -> 0 | E38: =+E37/0.71 -> 0 | G38: =+G37/0.71 -> 0 | H38: =+H37/0.71 -> 0 | I38: =+I37/0.71 -> 0
A39: =مجاميع!A22 -> 0 | B39: =مجاميع!B22 -> 0 | C39: =مجاميع!C22 -> 0 | D39: =مجاميع!D22 -> 0 | E39: =مجاميع!I22 -> 0 | F39: 0.18 | G39: =+(C39*E39)*(F39)+(C39*E39) -> 0 | H39: =مجاميع!E22 -> 0 | I39: =+H39-G39 -> 0 | J39: =(H39-G39)/H39 -> #DIV/0!
D40: =+D39/0.71 -> 0 | E40: =+E39/0.71 -> 0 | G40: =+G39/0.71 -> 0 | H40: =+H39/0.71 -> 0 | I40: =+I39/0.71 -> 0
A41: =مجاميع!A23 -> 0 | B41: =مجاميع!B23 -> 0 | C41: =مجاميع!C23 -> 0 | D41: =مجاميع!D23 -> 0 | E41: =مجاميع!I23 -> 0 | F41: 0.18 | G41: =+(C41*E41)*(F41)+(C41*E41) -> 0 | H41: =مجاميع!E23 -> 0 | I41: =+H41-G41 -> 0 | J41: =(H41-G41)/H41 -> #DIV/0!
...

Sheet مجاميع
A1: OrderNo | B1: OrderDate | C1: Name | F1: There is a 100 kg bonus
A2: 2600325 | B2: 46084 | C2: BakeMark USA LLC
A4: ItemNo | B4: ItemDesc_Ara | C4: Qty | D4: U.Price | E4: TotalValue | F4: كلفة المعادلات | G4: المستودعات | H4: تكلفة الفاتورة | I4: COST | J4: COST INV | K4: Diff | L4: U*C | M4: Diff
A5: FGM.FIL.3535.0343 | B5: Kunafa Pistachio Crunchy Filling ( BAKE MARK - SING ) 6 Pail *1 kg | C5: 5070 | D5: 5.921 | E5: 30021.498 | F5: =IFERROR(VLOOKUP(A5,'[1]كلفة المواد الخام معادلات تصنيع'!$A:$C,3,0),0) -> 2.4780498 | G5: =IFERROR(VLOOKUP(A5,'[1]قيمة المخزون'!$A:$C,3,0),0) -> 0 | H5: =+IFERROR(VLOOKUP(A5,[2]Sheet2!$A:$C,3,0),0) -> 0 | I5: =+J5 -> 2.3253 | J5: 2.3253 | K5: =+I5-J5 -> 0 | L5: =+D5*C5 -> 30019.47 | M5: =+E5-L5 -> 2.028
A6: FGM.FIL.3536.0343 | B6: Kunafa Pistachio Filling ( BAKE MARK - SING ) 4 Pail *5 kg | C6: 400 | D6: 5.921 | E6: 2368.56 | F6: =IFERROR(VLOOKUP(A6,'[1]كلفة المواد الخام معادلات تصنيع'!$A:$C,3,0),0) -> 2.3849756 | G6: =IFERROR(VLOOKUP(A6,'[1]قيمة المخزون'!$A:$C,3,0),0) -> 0 | H6: =+IFERROR(VLOOKUP(A6,[2]Sheet2!$A:$C,3,0),0) -> 0 | I6: =+J6 -> 2.2266 | J6: 2.2266 | K6: =+I6-J6 -> 0 | L6: =+D6*C6 -> 2368.4 | M6: =+E6-L6 -> 0.16
A7: FGM.FIL.3537.0343 | B7: Bisco Crunchy Filling ( BAKE MARK - SING ) 6 Pail *1 kg | C7: 1014 | D7: 3.656 | E7: 3707.691 | F7: =IFERROR(VLOOKUP(A7,'[1]كلفة المواد الخام معادلات تصنيع'!$A:$C,3,0),0) -> 1.7351842 | G7: =IFERROR(VLOOKUP(A7,'[1]قيمة المخزون'!$A:$C,3,0),0) -> 0 | H7: =+IFERROR(VLOOKUP(A7,[2]Sheet2!$A:$C,3,0),0) -> 0 | I7: =+J7 -> 1.6663 | J7: 1.6663 | K7: =+I7-J7 -> 0 | L7: =+D7*C7 -> 3707.184 | M7: =+E7-L7 -> 0.507
A8: FGM.FIL.3871.0343 | B8: Kunafa Peanut Butter Filling ( Bake Mark - SING ) 6Pail *1 kg | C8: 300 | D8: 2.982 | E8: 894.6 | F8: =IFERROR(VLOOKUP(A8,'[1]كلفة المواد الخام معادلات تصنيع'!$A:$C,3,0),0) -> 0 | G8: =IFERROR(VLOOKUP(A8,'[1]قيمة المخزون'!$A:$C,3,0),0) -> 0 | H8: =+IFERROR(VLOOKUP(A8,[2]Sheet2!$A:$C,3,0),0) -> 0 | I8: =+J8 -> 2.2401 | J8: 2.2401 | K8: =+I8-J8 -> 0 | L8: =+D8*C8 -> 894.6 | M8: =+E8-L8 -> 0
A9: FGM.FIL.3873.0343 | B9: Milk Chocolate Cream With Fuellitine Crunchy (Bake Mark - SING ) 6 Pail * 1 KG | C9: 102 | D9: 4.047 | E9: 412.794 | F9: =IFERROR(VLOOKUP(A9,'[1]كلفة المواد الخام معادلات تصنيع'!$A:$C,3,0),0) -> 0 | G9: =IFERROR(VLOOKUP(A9,'[1]قيمة المخزون'!$A:$C,3,0),0) -> 0 | H9: =+IFERROR(VLOOKUP(A9,[2]Sheet2!$A:$C,3,0),0) -> 0 | I9: =+J9 -> 2.0704 | J9: 2.0704 | K9: =+I9-J9 -> 0 | L9: =+D9*C9 -> 412.794 | M9: =+E9-L9 -> 0
A10: FGM.FIL.3874.0343 | B10: Milk Chocolate Cream With Fuellitine ( Bake Mark - SING ) 4 Pail *5 kg | C10: 2000 | D10: 4.047 | E10: 8094 | F10: =IFERROR(VLOOKUP(A10,'[1]كلفة المواد الخام معادلات تصنيع'!$A:$C,3,0),0) -> 0 | G10: =IFERROR(VLOOKUP(A10,'[1]قيمة المخزون'!$A:$C,3,0),0) -> 0 | H10: =+IFERROR(VLOOKUP(A10,[2]Sheet2!$A:$C,3,0),0) -> 0 | I10: =+J10 -> 1.9716 | J10: 1.9716 | K10: =+I10-J10 -> 0 | L10: =+D10*C10 -> 8094 | M10: =+E10-L10 -> 0
F11: =IFERROR(VLOOKUP(A11,'[1]كلفة المواد الخام معادلات تصنيع'!$A:$C,3,0),0) -> 0 | G11: =IFERROR(VLOOKUP(A11,'[1]قيمة المخزون'!$A:$C,3,0),0) -> 0 | H11: =+IFERROR(VLOOKUP(A11,[2]Sheet2!$A:$C,3,0),0) -> 0 | I11: =+J11 -> 0 | J11: 0 | K11: =+I11-J11 -> 0 | L11: =+D11*C11 -> 0 | M11: =+E11-L11 -> 0
F12: =IFERROR(VLOOKUP(A12,'[1]كلفة المواد الخام معادلات تصنيع'!$A:$C,3,0),0) -> 0 | G12: =IFERROR(VLOOKUP(A12,'[1]قيمة المخزون'!$A:$C,3,0),0) -> 0 | H12: =+IFERROR(VLOOKUP(A12,[2]Sheet2!$A:$C,3,0),0) -> 0 | I12: =+J12 -> 0 | J12: 0 | K12: =+I12-J12 -> 0 | L12: =+D12*C12 -> 0 | M12: =+E12-L12 -> 0
F13: =IFERROR(VLOOKUP(A13,'[1]كلفة المواد الخام معادلات تصنيع'!$A:$C,3,0),0) -> 0 | G13: =IFERROR(VLOOKUP(A13,'[1]قيمة المخزون'!$A:$C,3,0),0) -> 0 | H13: =+IFERROR(VLOOKUP(A13,[2]Sheet2!$A:$C,3,0),0) -> 0 | I13: =+J13 -> 0 | J13: 0 | K13: =+I13-J13 -> 0 | L13: =+D13*C13 -> 0 | M13: =+E13-L13 -> 0
F14: =IFERROR(VLOOKUP(A14,'[1]كلفة المواد الخام معادلات تصنيع'!$A:$C,3,0),0) -> 0 | G14: =IFERROR(VLOOKUP(A14,'[1]قيمة المخزون'!$A:$C,3,0),0) -> 0 | H14: =+IFERROR(VLOOKUP(A14,[2]Sheet2!$A:$C,3,0),0) -> 0 | I14: =+J14 -> 0 | J14: 0 | K14: =+I14-J14 -> 0 | L14: =+D14*C14 -> 0 | M14: =+E14-L14 -> 0
F15: =IFERROR(VLOOKUP(A15,'[1]كلفة المواد الخام معادلات تصنيع'!$A:$C,3,0),0) -> 0 | G15: =IFERROR(VLOOKUP(A15,'[1]قيمة المخزون'!$A:$C,3,0),0) -> 0 | H15: =+IFERROR(VLOOKUP(A15,[2]Sheet2!$A:$C,3,0),0) -> 0 | I15: =+J15 -> 0 | J15: 0 | K15: =+I15-J15 -> 0 | L15: =+D15*C15 -> 0 | M15: =+E15-L15 -> 0
F16: =IFERROR(VLOOKUP(A16,'[1]كلفة المواد الخام معادلات تصنيع'!$A:$C,3,0),0) -> 0 | G16: =IFERROR(VLOOKUP(A16,'[1]قيمة المخزون'!$A:$C,3,0),0) -> 0 | H16: =+IFERROR(VLOOKUP(A16,[2]Sheet2!$A:$C,3,0),0) -> 0 | I16: =+J16 -> 0 | J16: 0 | K16: =+I16-J16 -> 0 | L16: =+D16*C16 -> 0 | M16: =+E16-L16 -> 0
F17: =IFERROR(VLOOKUP(A17,'[1]كلفة المواد الخام معادلات تصنيع'!$A:$C,3,0),0) -> 0 | G17: =IFERROR(VLOOKUP(A17,'[1]قيمة المخزون'!$A:$C,3,0),0) -> 0 | H17: =+IFERROR(VLOOKUP(A17,[2]Sheet2!$A:$C,3,0),0) -> 0 | I17: =+J17 -> 0 | J17: 0 | K17: =+I17-J17 -> 0 | L17: =+D17*C17 -> 0 | M17: =+E17-L17 -> 0
F18: =IFERROR(VLOOKUP(A18,'[1]كلفة المواد الخام معادلات تصنيع'!$A:$C,3,0),0) -> 0 | G18: =IFERROR(VLOOKUP(A18,'[1]قيمة المخزون'!$A:$C,3,0),0) -> 0 | H18: =+IFERROR(VLOOKUP(A18,[2]Sheet2!$A:$C,3,0),0) -> 0 | I18: =+J18 -> 0 | J18: 0 | K18: =+I18-J18 -> 0 | L18: =+D18*C18 -> 0 | M18: =+E18-L18 -> 0
F19: =IFERROR(VLOOKUP(A19,'[1]كلفة المواد الخام معادلات تصنيع'!$A:$C,3,0),0) -> 0 | G19: =IFERROR(VLOOKUP(A19,'[1]قيمة المخزون'!$A:$C,3,0),0) -> 0 | H19: =+IFERROR(VLOOKUP(A19,[2]Sheet2!$A:$C,3,0),0) -> 0 | I19: =+J19 -> 0 | J19: 0 | K19: =+I19-J19 -> 0 | L19: =+D19*C19 -> 0 | M19: =+E19-L19 -> 0
D20: =IFERROR(E20/C20,0) -> 0 | E20: =+N20*-1 -> 0 | F20: =IFERROR(VLOOKUP(A20,'[1]كلفة المواد الخام معادلات تصنيع'!$A:$C,3,0),0) -> 0 | G20: =IFERROR(VLOOKUP(A20,'[1]قيمة المخزون'!$A:$C,3,0),0) -> 0 | H20: =+IFERROR(VLOOKUP(A20,[2]Sheet2!$A:$C,3,0),0) -> 0 | I20: =+J20 -> 0 | K20: =+I20-J20 -> 0 | L20: =+D20*C20 -> 0 | M20: =+E20-L20 -> 0
D21: =IFERROR(E21/C21,0) -> 0 | E21: =+N21*-1 -> 0 | F21: =IFERROR(VLOOKUP(A21,'[1]كلفة المواد الخام معادلات تصنيع'!$A:$C,3,0),0) -> 0 | G21: =IFERROR(VLOOKUP(A21,'[1]قيمة المخزون'!$A:$C,3,0),0) -> 0 | H21: =+IFERROR(VLOOKUP(A21,[2]Sheet2!$A:$C,3,0),0) -> 0 | I21: =+J21 -> 0 | K21: =+I21-J21 -> 0 | L21: =+D21*C21 -> 0 | M21: =+E21-L21 -> 0
D22: =IFERROR(E22/C22,0) -> 0 | E22: =+N22*-1 -> 0 | F22: =IFERROR(VLOOKUP(A22,'[1]كلفة المواد الخام معادلات تصنيع'!$A:$C,3,0),0) -> 0 | G22: =IFERROR(VLOOKUP(A22,'[1]قيمة المخزون'!$A:$C,3,0),0) -> 0 | H22: =+IFERROR(VLOOKUP(A22,[2]Sheet2!$A:$C,3,0),0) -> 0 | I22: =+J22 -> 0 | K22: =+I22-J22 -> 0 | L22: =+D22*C22 -> 0 | M22: =+E22-L22 -> 0
D23: =IFERROR(E23/C23,0) -> 0 | E23: =+N23*-1 -> 0 | F23: =IFERROR(VLOOKUP(A23,'[1]كلفة المواد الخام معادلات تصنيع'!$A:$C,3,0),0) -> 0 | G23: =IFERROR(VLOOKUP(A23,'[1]قيمة المخزون'!$A:$C,3,0),0) -> 0 | H23: =+IFERROR(VLOOKUP(A23,[2]Sheet2!$A:$C,3,0),0) -> 0 | I23: =+J23 -> 0 | K23: =+I23-J23 -> 0 | L23: =+D23*C23 -> 0 | M23: =+E23-L23 -> 0
D24: =IFERROR(E24/C24,0) -> 0 | E24: =+N24*-1 -> 0 | F24: =IFERROR(VLOOKUP(A24,'[1]كلفة المواد الخام معادلات تصنيع'!$A:$C,3,0),0) -> 0 | G24: =IFERROR(VLOOKUP(A24,'[1]قيمة المخزون'!$A:$C,3,0),0) -> 0 | H24: =+IFERROR(VLOOKUP(A24,[2]Sheet2!$A:$C,3,0),0) -> 0 | I24: =+J24 -> 0 | K24: =+I24-J24 -> 0 | L24: =+D24*C24 -> 0 | M24: =+E24-L24 -> 0
D25: =IFERROR(E25/C25,0) -> 0 | E25: =+N25*-1 -> 0 | F25: =IFERROR(VLOOKUP(A25,'[1]كلفة المواد الخام معادلات تصنيع'!$A:$C,3,0),0) -> 0 | G25: =IFERROR(VLOOKUP(A25,'[1]قيمة المخزون'!$A:$C,3,0),0) -> 0 | H25: =+IFERROR(VLOOKUP(A25,[2]Sheet2!$A:$C,3,0),0) -> 0 | I25: =+J25 -> 0 | K25: =+I25-J25 -> 0 | L25: =+D25*C25 -> 0 | M25: =+E25-L25 -> 0
D26: =IFERROR(E26/C26,0) -> 0 | E26: =+N26*-1 -> 0 | F26: =IFERROR(VLOOKUP(A26,'[1]كلفة المواد الخام معادلات تصنيع'!$A:$C,3,0),0) -> 0 | G26: =IFERROR(VLOOKUP(A26,'[1]قيمة المخزون'!$A:$C,3,0),0) -> 0 | H26: =+IFERROR(VLOOKUP(A26,[2]Sheet2!$A:$C,3,0),0) -> 0 | I26: =+J26 -> 0 | K26: =+I26-J26 -> 0 | L26: =+D26*C26 -> 0 | M26: =+E26-L26 -> 0
D27: =IFERROR(E27/C27,0) -> 0 | E27: =+N27*-1 -> 0 | F27: =IFERROR(VLOOKUP(A27,'[1]كلفة المواد الخام معادلات تصنيع'!$A:$C,3,0),0) -> 0 | G27: =IFERROR(VLOOKUP(A27,'[1]قيمة المخزون'!$A:$C,3,0),0) -> 0 | H27: =+IFERROR(VLOOKUP(A27,[2]Sheet2!$A:$C,3,0),0) -> 0 | I27: =+J27 -> 0 | K27: =+I27-J27 -> 0 | L27: =+D27*C27 -> 0 | M27: =+E27-L27 -> 0
D28: =IFERROR(E28/C28,0) -> 0 | E28: =+N28*-1 -> 0 | F28: =IFERROR(VLOOKUP(A28,'[1]كلفة المواد الخام معادلات تصنيع'!$A:$C,3,0),0) -> 0 | G28: =IFERROR(VLOOKUP(A28,'[1]قيمة المخزون'!$A:$C,3,0),0) -> 0 | H28: =+IFERROR(VLOOKUP(A28,[2]Sheet2!$A:$C,3,0),0) -> 0 | I28: =+J28 -> 0 | K28: =+I28-J28 -> 0 | L28: =+D28*C28 -> 0 | M28: =+E28-L28 -> 0
D29: =IFERROR(E29/C29,0) -> 0 | E29: =+N29*-1 -> 0 | F29: =IFERROR(VLOOKUP(A29,'[1]كلفة المواد الخام معادلات تصنيع'!$A:$C,3,0),0) -> 0 | G29: =IFERROR(VLOOKUP(A29,'[1]قيمة المخزون'!$A:$C,3,0),0) -> 0 | H29: =+IFERROR(VLOOKUP(A29,[2]Sheet2!$A:$C,3,0),0) -> 0 | I29: =+J29 -> 0 | K29: =+I29-J29 -> 0 | L29: =+D29*C29 -> 0 | M29: =+E29-L29 -> 0
D30: =IFERROR(E30/C30,0) -> 0 | E30: =+N30*-1 -> 0 | F30: =IFERROR(VLOOKUP(A30,'[1]كلفة المواد الخام معادلات تصنيع'!$A:$C,3,0),0) -> 0 | G30: =IFERROR(VLOOKUP(A30,'[1]قيمة المخزون'!$A:$C,3,0),0) -> 0 | H30: =+IFERROR(VLOOKUP(A30,[2]Sheet2!$A:$C,3,0),0) -> 0 | I30: =+J30 -> 0 | K30: =+I30-J30 -> 0 | L30: =+D30*C30 -> 0 | M30: =+E30-L30 -> 0
D31: =IFERROR(E31/C31,0) -> 0 | E31: =+N31*-1 -> 0 | F31: =IFERROR(VLOOKUP(A31,'[1]كلفة المواد الخام معادلات تصنيع'!$A:$C,3,0),0) -> 0 | G31: =IFERROR(VLOOKUP(A31,'[1]قيمة المخزون'!$A:$C,3,0),0) -> 0 | H31: =+IFERROR(VLOOKUP(A31,[2]Sheet2!$A:$C,3,0),0) -> 0 | I31: =+J31 -> 0 | K31: =+I31-J31 -> 0 | L31: =+D31*C31 -> 0 | M31: =+E31-L31 -> 0
... D53: =IFERROR(E53/C53,0) -> 0 | E53: =+N53*-1 -> 0 | F53: =IFERROR(VLOOKUP(A53,'[1]كلفة المواد الخام معادلات تصنيع'!$A:$C,3,0),0) -> 0 | G53: =IFERROR(VLOOKUP(A53,'[1]قيمة المخزون'!$A:$C,3,0),0) -> 0 | H53: =+IFERROR(VLOOKUP(A53,[2]Sheet2!$A:$C,3,0),0) -> 0 | I53: =+J53 -> 0 | K53: =+I53-J53 -> 0 | L53: =+D53*C53 -> 0 | M53: =+E53-L53 -> 0
